Workbook

Sheet W&M-DS.M-QS
A1: DS | B1: Décembre | D1: Novembre
B2: Magasin FO | C2: Magasin BO | D2: Magasin FO | E2: Magasin BO
A3: Appels comptabilisés | B3: ='Daily-DS.M-QS'!BJ3+'Daily-DS.M-QS'!BH3+'Daily-DS.M-QS'!BF3+'Daily-DS.M-QS'!BD3+'Daily-DS.M-QS'!BB3+'Daily-DS.M-QS'!AZ3+'Daily-DS.M-QS'!AX3+'Daily-DS.M-QS'!AV3+'Daily-DS.M-QS'!AT3+'Daily-DS.M-QS'!AR3+'Daily-DS.M-QS'!AP3+'Daily-DS.M-QS'!AN3+'Daily-DS.M-QS'!AL3+'Daily-DS.M-QS'!AJ3+'Daily-DS.M-QS'!AH3+'Daily-DS.M-QS'!AF3+'Daily-DS.M-QS'!AD3+'Daily-DS.M-QS'!AB3+'Daily-DS.M-QS'!Z3+'Daily-DS.M-QS'!X3+'Daily-DS.M-QS'!V3+'Daily-DS.M-QS'!T3+'Daily-DS.M-QS'!R3+'Daily-DS.M-QS'!P3+'Daily-DS.M-QS'!N3+'Daily-DS.M-QS'!L3+'Daily-DS.M-QS'!J3+'Daily-DS.M-QS'!H3+'Daily-DS.M-QS'!F3+'Daily-DS.M-QS'!D3+'Daily-DS.M-QS'!B3 -> 1574 | C3: ='Daily-DS.M-QS'!BK3+'Daily-DS.M-QS'!BI3+'Daily-DS.M-QS'!BG3+'Daily-DS.M-QS'!BE3+'Daily-DS.M-QS'!BC3+'Daily-DS.M-QS'!BA3+'Daily-DS.M-QS'!AY3+'Daily-DS.M-QS'!AW3+'Daily-DS.M-QS'!AU3+'Daily-DS.M-QS'!AS3+'Daily-DS.M-QS'!AQ3+'Daily-DS.M-QS'!AO3+'Daily-DS.M-QS'!AM3+'Daily-DS.M-QS'!AK3+'Daily-DS.M-QS'!AI3+'Daily-DS.M-QS'!AG3+'Daily-DS.M-QS'!AE3+'Daily-DS.M-QS'!AC3+'Daily-DS.M-QS'!AA3+'Daily-DS.M-QS'!Y3+'Daily-DS.M-QS'!W3+'Daily-DS.M-QS'!U3+'Daily-DS.M-QS'!S3+'Daily-DS.M-QS'!Q3+'Daily-DS.M-QS'!O3+'Daily-DS.M-QS'!M3+'Daily-DS.M-QS'!K3+'Daily-DS.M-QS'!I3+'Daily-DS.M-QS'!G3+'Daily-DS.M-QS'!E3+'Daily-DS.M-QS'!C3 -> 1219 | D3: ='Daily-DS.M-QS'!DR3+'Daily-DS.M-QS'!DP3+'Daily-DS.M-QS'!DN3+'Daily-DS.M-QS'!DL3+'Daily-DS.M-QS'!DJ3+'Daily-DS.M-QS'!DH3+'Daily-DS.M-QS'!DF3+'Daily-DS.M-QS'!DD3+'Daily-DS.M-QS'!DB3+'Daily-DS.M-QS'!CZ3+'Daily-DS.M-QS'!CX3+'Daily-DS.M-QS'!CV3+'Daily-DS.M-QS'!CT3+'Daily-DS.M-QS'!CR3+'Daily-DS.M-QS'!CP3+'Daily-DS.M-QS'!CN3+'Daily-DS.M-QS'!CL3+'Daily-DS.M-QS'!CJ3+'Daily-DS.M-QS'!CH3+'Daily-DS.M-QS'!CF3+'Daily-DS.M-QS'!CD3+'Daily-DS.M-QS'!CB3+'Daily-DS.M-QS'!BZ3+'Daily-DS.M-QS'!BX3+'Daily-DS.M-QS'!BV3+'Daily-DS.M-QS'!BT3+'Daily-DS.M-QS'!BR3+'Daily-DS.M-QS'!BP3+'Daily-DS.M-QS'!BN3+'Daily-DS.M-QS'!BL3 -> 3097 | E3: ='Daily-DS.M-QS'!DS3+'Daily-DS.M-QS'!DQ3+'Daily-DS.M-QS'!DO3+'Daily-DS.M-QS'!DM3+'Daily-DS.M-QS'!DK3+'Daily-DS.M-QS'!DI3+'Daily-DS.M-QS'!DG3+'Daily-DS.M-QS'!DE3+'Daily-DS.M-QS'!DC3+'Daily-DS.M-QS'!DA3+'Daily-DS.M-QS'!CY3+'Daily-DS.M-QS'!CW3+'Daily-DS.M-QS'!CU3+'Daily-DS.M-QS'!CS3+'Daily-DS.M-QS'!CQ3+'Daily-DS.M-QS'!CO3+'Daily-DS.M-QS'!CM3+'Daily-DS.M-QS'!CK3+'Daily-DS.M-QS'!CI3+'Daily-DS.M-QS'!CG3+'Daily-DS.M-QS'!CE3+'Daily-DS.M-QS'!CC3+'Daily-DS.M-QS'!CA3+'Daily-DS.M-QS'!BY3+'Daily-DS.M-QS'!BW3+'Daily-DS.M-QS'!BU3+'Daily-DS.M-QS'!BS3+'Daily-DS.M-QS'!BQ3+'Daily-DS.M-QS'!BO3+'Daily-DS.M-QS'!BM3 -> 1767
A4: Appels Répondus | B4: ='Daily-DS.M-QS'!BJ4+'Daily-DS.M-QS'!BH4+'Daily-DS.M-QS'!BF4+'Daily-DS.M-QS'!BD4+'Daily-DS.M-QS'!BB4+'Daily-DS.M-QS'!AZ4+'Daily-DS.M-QS'!AX4+'Daily-DS.M-QS'!AV4+'Daily-DS.M-QS'!AT4+'Daily-DS.M-QS'!AR4+'Daily-DS.M-QS'!AP4+'Daily-DS.M-QS'!AN4+'Daily-DS.M-QS'!AL4+'Daily-DS.M-QS'!AJ4+'Daily-DS.M-QS'!AH4+'Daily-DS.M-QS'!AF4+'Daily-DS.M-QS'!AD4+'Daily-DS.M-QS'!AB4+'Daily-DS.M-QS'!Z4+'Daily-DS.M-QS'!X4+'Daily-DS.M-QS'!V4+'Daily-DS.M-QS'!T4+'Daily-DS.M-QS'!R4+'Daily-DS.M-QS'!P4+'Daily-DS.M-QS'!N4+'Daily-DS.M-QS'!L4+'Daily-DS.M-QS'!J4+'Daily-DS.M-QS'!H4+'Daily-DS.M-QS'!F4+'Daily-DS.M-QS'!D4+'Daily-DS.M-QS'!B4 -> 1535 | C4: ='Daily-DS.M-QS'!BK4+'Daily-DS.M-QS'!BI4+'Daily-DS.M-QS'!BG4+'Daily-DS.M-QS'!BE4+'Daily-DS.M-QS'!BC4+'Daily-DS.M-QS'!BA4+'Daily-DS.M-QS'!AY4+'Daily-DS.M-QS'!AW4+'Daily-DS.M-QS'!AU4+'Daily-DS.M-QS'!AS4+'Daily-DS.M-QS'!AQ4+'Daily-DS.M-QS'!AO4+'Daily-DS.M-QS'!AM4+'Daily-DS.M-QS'!AK4+'Daily-DS.M-QS'!AI4+'Daily-DS.M-QS'!AG4+'Daily-DS.M-QS'!AE4+'Daily-DS.M-QS'!AC4+'Daily-DS.M-QS'!AA4+'Daily-DS.M-QS'!Y4+'Daily-DS.M-QS'!W4+'Daily-DS.M-QS'!U4+'Daily-DS.M-QS'!S4+'Daily-DS.M-QS'!Q4+'Daily-DS.M-QS'!O4+'Daily-DS.M-QS'!M4+'Daily-DS.M-QS'!K4+'Daily-DS.M-QS'!I4+'Daily-DS.M-QS'!G4+'Daily-DS.M-QS'!E4+'Daily-DS.M-QS'!C4 -> 1187 | D4: ='Daily-DS.M-QS'!DR4+'Daily-DS.M-QS'!DP4+'Daily-DS.M-QS'!DN4+'Daily-DS.M-QS'!DL4+'Daily-DS.M-QS'!DJ4+'Daily-DS.M-QS'!DH4+'Daily-DS.M-QS'!DF4+'Daily-DS.M-QS'!DD4+'Daily-DS.M-QS'!DB4+'Daily-DS.M-QS'!CZ4+'Daily-DS.M-QS'!CX4+'Daily-DS.M-QS'!CV4+'Daily-DS.M-QS'!CT4+'Daily-DS.M-QS'!CR4+'Daily-DS.M-QS'!CP4+'Daily-DS.M-QS'!CN4+'Daily-DS.M-QS'!CL4+'Daily-DS.M-QS'!CJ4+'Daily-DS.M-QS'!CH4+'Daily-DS.M-QS'!CF4+'Daily-DS.M-QS'!CD4+'Daily-DS.M-QS'!CB4+'Daily-DS.M-QS'!BZ4+'Daily-DS.M-QS'!BX4+'Daily-DS.M-QS'!BV4+'Daily-DS.M-QS'!BT4+'Daily-DS.M-QS'!BR4+'Daily-DS.M-QS'!BP4+'Daily-DS.M-QS'!BN4+'Daily-DS.M-QS'!BL4 -> 2897 | E4: ='Daily-DS.M-QS'!DS4+'Daily-DS.M-QS'!DQ4+'Daily-DS.M-QS'!DO4+'Daily-DS.M-QS'!DM4+'Daily-DS.M-QS'!DK4+'Daily-DS.M-QS'!DI4+'Daily-DS.M-QS'!DG4+'Daily-DS.M-QS'!DE4+'Daily-DS.M-QS'!DC4+'Daily-DS.M-QS'!DA4+'Daily-DS.M-QS'!CY4+'Daily-DS.M-QS'!CW4+'Daily-DS.M-QS'!CU4+'Daily-DS.M-QS'!CS4+'Daily-DS.M-QS'!CQ4+'Daily-DS.M-QS'!CO4+'Daily-DS.M-QS'!CM4+'Daily-DS.M-QS'!CK4+'Daily-DS.M-QS'!CI4+'Daily-DS.M-QS'!CG4+'Daily-DS.M-QS'!CE4+'Daily-DS.M-QS'!CC4+'Daily-DS.M-QS'!CA4+'Daily-DS.M-QS'!BY4+'Daily-DS.M-QS'!BW4+'Daily-DS.M-QS'!BU4+'Daily-DS.M-QS'!BS4+'Daily-DS.M-QS'!BQ4+'Daily-DS.M-QS'!BO4+'Daily-DS.M-QS'!BM4 -> 1737
A5: Appels Perdus | B5: ='Daily-DS.M-QS'!BJ5+'Daily-DS.M-QS'!BH5+'Daily-DS.M-QS'!BF5+'Daily-DS.M-QS'!BD5+'Daily-DS.M-QS'!BB5+'Daily-DS.M-QS'!AZ5+'Daily-DS.M-QS'!AX5+'Daily-DS.M-QS'!AV5+'Daily-DS.M-QS'!AT5+'Daily-DS.M-QS'!AR5+'Daily-DS.M-QS'!AP5+'Daily-DS.M-QS'!AN5+'Daily-DS.M-QS'!AL5+'Daily-DS.M-QS'!AJ5+'Daily-DS.M-QS'!AH5+'Daily-DS.M-QS'!AF5+'Daily-DS.M-QS'!AD5+'Daily-DS.M-QS'!AB5+'Daily-DS.M-QS'!Z5+'Daily-DS.M-QS'!X5+'Daily-DS.M-QS'!V5+'Daily-DS.M-QS'!T5+'Daily-DS.M-QS'!R5+'Daily-DS.M-QS'!P5+'Daily-DS.M-QS'!N5+'Daily-DS.M-QS'!L5+'Daily-DS.M-QS'!J5+'Daily-DS.M-QS'!H5+'Daily-DS.M-QS'!F5+'Daily-DS.M-QS'!D5+'Daily-DS.M-QS'!B5 -> 39 | C5: ='Daily-DS.M-QS'!BK5+'Daily-DS.M-QS'!BI5+'Daily-DS.M-QS'!BG5+'Daily-DS.M-QS'!BE5+'Daily-DS.M-QS'!BC5+'Daily-DS.M-QS'!BA5+'Daily-DS.M-QS'!AY5+'Daily-DS.M-QS'!AW5+'Daily-DS.M-QS'!AU5+'Daily-DS.M-QS'!AS5+'Daily-DS.M-QS'!AQ5+'Daily-DS.M-QS'!AO5+'Daily-DS.M-QS'!AM5+'Daily-DS.M-QS'!AK5+'Daily-DS.M-QS'!AI5+'Daily-DS.M-QS'!AG5+'Daily-DS.M-QS'!AE5+'Daily-DS.M-QS'!AC5+'Daily-DS.M-QS'!AA5+'Daily-DS.M-QS'!Y5+'Daily-DS.M-QS'!W5+'Daily-DS.M-QS'!U5+'Daily-DS.M-QS'!S5+'Daily-DS.M-QS'!Q5+'Daily-DS.M-QS'!O5+'Daily-DS.M-QS'!M5+'Daily-DS.M-QS'!K5+'Daily-DS.M-QS'!I5+'Daily-DS.M-QS'!G5+'Daily-DS.M-QS'!E5+'Daily-DS.M-QS'!C5 -> 32 | D5: ='Daily-DS.M-QS'!DR5+'Daily-DS.M-QS'!DP5+'Daily-DS.M-QS'!DN5+'Daily-DS.M-QS'!DL5+'Daily-DS.M-QS'!DJ5+'Daily-DS.M-QS'!DH5+'Daily-DS.M-QS'!DF5+'Daily-DS.M-QS'!DD5+'Daily-DS.M-QS'!DB5+'Daily-DS.M-QS'!CZ5+'Daily-DS.M-QS'!CX5+'Daily-DS.M-QS'!CV5+'Daily-DS.M-QS'!CT5+'Daily-DS.M-QS'!CR5+'Daily-DS.M-QS'!CP5+'Daily-DS.M-QS'!CN5+'Daily-DS.M-QS'!CL5+'Daily-DS.M-QS'!CJ5+'Daily-DS.M-QS'!CH5+'Daily-DS.M-QS'!CF5+'Daily-DS.M-QS'!CD5+'Daily-DS.M-QS'!CB5+'Daily-DS.M-QS'!BZ5+'Daily-DS.M-QS'!BX5+'Daily-DS.M-QS'!BV5+'Daily-DS.M-QS'!BT5+'Daily-DS.M-QS'!BR5+'Daily-DS.M-QS'!BP5+'Daily-DS.M-QS'!BN5+'Daily-DS.M-QS'!BL5 -> 200 | E5: ='Daily-DS.M-QS'!DS5+'Daily-DS.M-QS'!DQ5+'Daily-DS.M-QS'!DO5+'Daily-DS.M-QS'!DM5+'Daily-DS.M-QS'!DK5+'Daily-DS.M-QS'!DI5+'Daily-DS.M-QS'!DG5+'Daily-DS.M-QS'!DE5+'Daily-DS.M-QS'!DC5+'Daily-DS.M-QS'!DA5+'Daily-DS.M-QS'!CY5+'Daily-DS.M-QS'!CW5+'Daily-DS.M-QS'!CU5+'Daily-DS.M-QS'!CS5+'Daily-DS.M-QS'!CQ5+'Daily-DS.M-QS'!CO5+'Daily-DS.M-QS'!CM5+'Daily-DS.M-QS'!CK5+'Daily-DS.M-QS'!CI5+'Daily-DS.M-QS'!CG5+'Daily-DS.M-QS'!CE5+'Daily-DS.M-QS'!CC5+'Daily-DS.M-QS'!CA5+'Daily-DS.M-QS'!BY5+'Daily-DS.M-QS'!BW5+'Daily-DS.M-QS'!BU5+'Daily-DS.M-QS'!BS5+'Daily-DS.M-QS'!BQ5+'Daily-DS.M-QS'!BO5+'Daily-DS.M-QS'!BM5 -> 30
A6: Appels Abandonnés | B6: ='Daily-DS.M-QS'!BJ6+'Daily-DS.M-QS'!BH6+'Daily-DS.M-QS'!BF6+'Daily-DS.M-QS'!BD6+'Daily-DS.M-QS'!BB6+'Daily-DS.M-QS'!AZ6+'Daily-DS.M-QS'!AX6+'Daily-DS.M-QS'!AV6+'Daily-DS.M-QS'!AT6+'Daily-DS.M-QS'!AR6+'Daily-DS.M-QS'!AP6+'Daily-DS.M-QS'!AN6+'Daily-DS.M-QS'!AL6+'Daily-DS.M-QS'!AJ6+'Daily-DS.M-QS'!AH6+'Daily-DS.M-QS'!AF6+'Daily-DS.M-QS'!AD6+'Daily-DS.M-QS'!AB6+'Daily-DS.M-QS'!Z6+'Daily-DS.M-QS'!X6+'Daily-DS.M-QS'!V6+'Daily-DS.M-QS'!T6+'Daily-DS.M-QS'!R6+'Daily-DS.M-QS'!P6+'Daily-DS.M-QS'!N6+'Daily-DS.M-QS'!L6+'Daily-DS.M-QS'!J6+'Daily-DS.M-QS'!H6+'Daily-DS.M-QS'!F6+'Daily-DS.M-QS'!D6+'Daily-DS.M-QS'!B6 -> 16 | C6: ='Daily-DS.M-QS'!BK6+'Daily-DS.M-QS'!BI6+'Daily-DS.M-QS'!BG6+'Daily-DS.M-QS'!BE6+'Daily-DS.M-QS'!BC6+'Daily-DS.M-QS'!BA6+'Daily-DS.M-QS'!AY6+'Daily-DS.M-QS'!AW6+'Daily-DS.M-QS'!AU6+'Daily-DS.M-QS'!AS6+'Daily-DS.M-QS'!AQ6+'Daily-DS.M-QS'!AO6+'Daily-DS.M-QS'!AM6+'Daily-DS.M-QS'!AK6+'Daily-DS.M-QS'!AI6+'Daily-DS.M-QS'!AG6+'Daily-DS.M-QS'!AE6+'Daily-DS.M-QS'!AC6+'Daily-DS.M-QS'!AA6+'Daily-DS.M-QS'!Y6+'Daily-DS.M-QS'!W6+'Daily-DS.M-QS'!U6+'Daily-DS.M-QS'!S6+'Daily-DS.M-QS'!Q6+'Daily-DS.M-QS'!O6+'Daily-DS.M-QS'!M6+'Daily-DS.M-QS'!K6+'Daily-DS.M-QS'!I6+'Daily-DS.M-QS'!G6+'Daily-DS.M-QS'!E6+'Daily-DS.M-QS'!C6 -> 14 | D6: ='Daily-DS.M-QS'!DR6+'Daily-DS.M-QS'!DP6+'Daily-DS.M-QS'!DN6+'Daily-DS.M-QS'!DL6+'Daily-DS.M-QS'!DJ6+'Daily-DS.M-QS'!DH6+'Daily-DS.M-QS'!DF6+'Daily-DS.M-QS'!DD6+'Daily-DS.M-QS'!DB6+'Daily-DS.M-QS'!CZ6+'Daily-DS.M-QS'!CX6+'Daily-DS.M-QS'!CV6+'Daily-DS.M-QS'!CT6+'Daily-DS.M-QS'!CR6+'Daily-DS.M-QS'!CP6+'Daily-DS.M-QS'!CN6+'Daily-DS.M-QS'!CL6+'Daily-DS.M-QS'!CJ6+'Daily-DS.M-QS'!CH6+'Daily-DS.M-QS'!CF6+'Daily-DS.M-QS'!CD6+'Daily-DS.M-QS'!CB6+'Daily-DS.M-QS'!BZ6+'Daily-DS.M-QS'!BX6+'Daily-DS.M-QS'!BV6+'Daily-DS.M-QS'!BT6+'Daily-DS.M-QS'!BR6+'Daily-DS.M-QS'!BP6+'Daily-DS.M-QS'!BN6+'Daily-DS.M-QS'!BL6 -> 99 | E6: ='Daily-DS.M-QS'!DS6+'Daily-DS.M-QS'!DQ6+'Daily-DS.M-QS'!DO6+'Daily-DS.M-QS'!DM6+'Daily-DS.M-QS'!DK6+'Daily-DS.M-QS'!DI6+'Daily-DS.M-QS'!DG6+'Daily-DS.M-QS'!DE6+'Daily-DS.M-QS'!DC6+'Daily-DS.M-QS'!DA6+'Daily-DS.M-QS'!CY6+'Daily-DS.M-QS'!CW6+'Daily-DS.M-QS'!CU6+'Daily-DS.M-QS'!CS6+'Daily-DS.M-QS'!CQ6+'Daily-DS.M-QS'!CO6+'Daily-DS.M-QS'!CM6+'Daily-DS.M-QS'!CK6+'Daily-DS.M-QS'!CI6+'Daily-DS.M-QS'!CG6+'Daily-DS.M-QS'!CE6+'Daily-DS.M-QS'!CC6+'Daily-DS.M-QS'!CA6+'Daily-DS.M-QS'!BY6+'Daily-DS.M-QS'!BW6+'Daily-DS.M-QS'!BU6+'Daily-DS.M-QS'!BS6+'Daily-DS.M-QS'!BQ6+'Daily-DS.M-QS'!BO6+'Daily-DS.M-QS'!BM6 -> 25
A7: QS | B7: =B4/B3 -> 0.97522236 | C7: =C4/C3 -> 0.97374897 | D7: =D4/D3 -> 0.93542138 | E7: =E4/E3 -> 0.98302207
A8: Taux des perdus | B8: =B5/B3 -> 0.024777637 | C8: =C5/C3 -> 0.026251025 | D8: =D5/D3 -> 0.064578624 | E8: =E5/E3 -> 0.016977929
A9: Taux des abandonnés | B9: =B6/B3 -> 0.010165184 | C9: =C6/C3 -> 0.011484824 | D9: =D6/D3 -> 0.031966419 | E9: =E6/E3 -> 0.014148274
A11: Durée Moy. d'attente | B11: =AVERAGE('Daily-DS.M-QS'!BJ11,'Daily-DS.M-QS'!BH11,'Daily-DS.M-QS'!BF11,'Daily-DS.M-QS'!BD11,'Daily-DS.M-QS'!BB11,'Daily-DS.M-QS'!AZ11,'Daily-DS.M-QS'!AX11,'Daily-DS.M-QS'!AV11,'Daily-DS.M-QS'!AT11,'Daily-DS.M-QS'!AR11,'Daily-DS.M-QS'!AP11,'Daily-DS.M-QS'!AN11,'Daily-DS.M-QS'!AL11,'Daily-DS.M-QS'!AJ11,'Daily-DS.M-QS'!AH11,'Daily-DS.M-QS'!AF11,'Daily-DS.M-QS'!AD11,'Daily-DS.M-QS'!AB11,'Daily-DS.M-QS'!Z11,'Daily-DS.M-QS'!X11,'Daily-DS.M-QS'!V11,'Daily-DS.M-QS'!T11,'Daily-DS.M-QS'!R11,'Daily-DS.M-QS'!P11,'Daily-DS.M-QS'!N11,'Daily-DS.M-QS'!L11,'Daily-DS.M-QS'!J11,'Daily-DS.M-QS'!H11,'Daily-DS.M-QS'!F11,'Daily-DS.M-QS'!D11+'Daily-DS.M-QS'!B11) -> 0.020261438 | C11: =AVERAGE('Daily-DS.M-QS'!BK11,'Daily-DS.M-QS'!BI11,'Daily-DS.M-QS'!BG11,'Daily-DS.M-QS'!BE11,'Daily-DS.M-QS'!BC11,'Daily-DS.M-QS'!BA11,'Daily-DS.M-QS'!AY11,'Daily-DS.M-QS'!AW11,'Daily-DS.M-QS'!AU11,'Daily-DS.M-QS'!AS11,'Daily-DS.M-QS'!AQ11,'Daily-DS.M-QS'!AO11,'Daily-DS.M-QS'!AM11,'Daily-DS.M-QS'!AK11,'Daily-DS.M-QS'!AI11,'Daily-DS.M-QS'!AG11,'Daily-DS.M-QS'!AE11,'Daily-DS.M-QS'!AC11,'Daily-DS.M-QS'!AA11,'Daily-DS.M-QS'!Y11,'Daily-DS.M-QS'!W11,'Daily-DS.M-QS'!U11,'Daily-DS.M-QS'!S11,'Daily-DS.M-QS'!Q11,'Daily-DS.M-QS'!O11,'Daily-DS.M-QS'!M11,'Daily-DS.M-QS'!K11,'Daily-DS.M-QS'!I11,'Daily-DS.M-QS'!G11,'Daily-DS.M-QS'!E11+'Daily-DS.M-QS'!C11) -> 0.020179739 | D11: =AVERAGE('Daily-DS.M-QS'!DR11,'Daily-DS.M-QS'!DP11,'Daily-DS.M-QS'!DN11,'Daily-DS.M-QS'!DL11,'Daily-DS.M-QS'!DJ11,'Daily-DS.M-QS'!DH11,'Daily-DS.M-QS'!DF11,'Daily-DS.M-QS'!DD11,'Daily-DS.M-QS'!DB11,'Daily-DS.M-QS'!CZ11,'Daily-DS.M-QS'!CX11,'Daily-DS.M-QS'!CV11,'Daily-DS.M-QS'!CT11,'Daily-DS.M-QS'!CR11,'Daily-DS.M-QS'!CP11,'Daily-DS.M-QS'!CN11,'Daily-DS.M-QS'!CL11,'Daily-DS.M-QS'!CJ11,'Daily-DS.M-QS'!CH11,'Daily-DS.M-QS'!CF11,'Daily-DS.M-QS'!CD11,'Daily-DS.M-QS'!CB11,'Daily-DS.M-QS'!BZ11,'Daily-DS.M-QS'!BX11,'Daily-DS.M-QS'!BV11,'Daily-DS.M-QS'!BT11,'Daily-DS.M-QS'!BR11,'Daily-DS.M-QS'!BP11,'Daily-DS.M-QS'!BN11,'Daily-DS.M-QS'!BL11) -> 0.030717593 | E11: =AVERAGE('Daily-DS.M-QS'!DS11,'Daily-DS.M-QS'!DQ11,'Daily-DS.M-QS'!DO11,'Daily-DS.M-QS'!DM11,'Daily-DS.M-QS'!DK11,'Daily-DS.M-QS'!DI11,'Daily-DS.M-QS'!DG11,'Daily-DS.M-QS'!DE11,'Daily-DS.M-QS'!DC11,'Daily-DS.M-QS'!DA11,'Daily-DS.M-QS'!CY11,'Daily-DS.M-QS'!CW11,'Daily-DS.M-QS'!CU11,'Daily-DS.M-QS'!CS11,'Daily-DS.M-QS'!CQ11,'Daily-DS.M-QS'!CO11,'Daily-DS.M-QS'!CM11,'Daily-DS.M-QS'!CK11,'Daily-DS.M-QS'!CI11,'Daily-DS.M-QS'!CG11,'Daily-DS.M-QS'!CE11,'Daily-DS.M-QS'!CC11,'Daily-DS.M-QS'!CA11,'Daily-DS.M-QS'!BY11,'Daily-DS.M-QS'!BW11,'Daily-DS.M-QS'!BU11,'Daily-DS.M-QS'!BS11,'Daily-DS.M-QS'!BQ11,'Daily-DS.M-QS'!BO11,'Daily-DS.M-QS'!BM11) -> 0.015925926
A12: Durée Moy. de communication | B12: =AVERAGE('Daily-DS.M-QS'!BJ12,'Daily-DS.M-QS'!BH12,'Daily-DS.M-QS'!BF12,'Daily-DS.M-QS'!BD12,'Daily-DS.M-QS'!BB12,'Daily-DS.M-QS'!AZ12,'Daily-DS.M-QS'!AX12,'Daily-DS.M-QS'!AV12,'Daily-DS.M-QS'!AT12,'Daily-DS.M-QS'!AR12,'Daily-DS.M-QS'!AP12,'Daily-DS.M-QS'!AN12,'Daily-DS.M-QS'!AL12,'Daily-DS.M-QS'!AJ12,'Daily-DS.M-QS'!AH12,'Daily-DS.M-QS'!AF12,'Daily-DS.M-QS'!AD12,'Daily-DS.M-QS'!AB12,'Daily-DS.M-QS'!Z12,'Daily-DS.M-QS'!X12,'Daily-DS.M-QS'!V12,'Daily-DS.M-QS'!T12,'Daily-DS.M-QS'!R12,'Daily-DS.M-QS'!P12,'Daily-DS.M-QS'!N12,'Daily-DS.M-QS'!L12,'Daily-DS.M-QS'!J12,'Daily-DS.M-QS'!H12,'Daily-DS.M-QS'!F12,'Daily-DS.M-QS'!D12+'Daily-DS.M-QS'!B12) -> 0.26789216 | C12: =AVERAGE('Daily-DS.M-QS'!BK12,'Daily-DS.M-QS'!BI12,'Daily-DS.M-QS'!BG12,'Daily-DS.M-QS'!BE12,'Daily-DS.M-QS'!BC12,'Daily-DS.M-QS'!BA12,'Daily-DS.M-QS'!AY12,'Daily-DS.M-QS'!AW12,'Daily-DS.M-QS'!AU12,'Daily-DS.M-QS'!AS12,'Daily-DS.M-QS'!AQ12,'Daily-DS.M-QS'!AO12,'Daily-DS.M-QS'!AM12,'Daily-DS.M-QS'!AK12,'Daily-DS.M-QS'!AI12,'Daily-DS.M-QS'!AG12,'Daily-DS.M-QS'!AE12,'Daily-DS.M-QS'!AC12,'Daily-DS.M-QS'!AA12,'Daily-DS.M-QS'!Y12,'Daily-DS.M-QS'!W12,'Daily-DS.M-QS'!U12,'Daily-DS.M-QS'!S12,'Daily-DS.M-QS'!Q12,'Daily-DS.M-QS'!O12,'Daily-DS.M-QS'!M12,'Daily-DS.M-QS'!K12,'Daily-DS.M-QS'!I12,'Daily-DS.M-QS'!G12,'Daily-DS.M-QS'!E12+'Daily-DS.M-QS'!C12) -> 0.18541667 | D12: =AVERAGE('Daily-DS.M-QS'!DR12,'Daily-DS.M-QS'!DP12,'Daily-DS.M-QS'!DN12,'Daily-DS.M-QS'!DL12,'Daily-DS.M-QS'!DJ12,'Daily-DS.M-QS'!DH12,'Daily-DS.M-QS'!DF12,'Daily-DS.M-QS'!DD12,'Daily-DS.M-QS'!DB12,'Daily-DS.M-QS'!CZ12,'Daily-DS.M-QS'!CX12,'Daily-DS.M-QS'!CV12,'Daily-DS.M-QS'!CT12,'Daily-DS.M-QS'!CR12,'Daily-DS.M-QS'!CP12,'Daily-DS.M-QS'!CN12,'Daily-DS.M-QS'!CL12,'Daily-DS.M-QS'!CJ12,'Daily-DS.M-QS'!CH12,'Daily-DS.M-QS'!CF12,'Daily-DS.M-QS'!CD12,'Daily-DS.M-QS'!CB12,'Daily-DS.M-QS'!BZ12,'Daily-DS.M-QS'!BX12,'Daily-DS.M-QS'!BV12,'Daily-DS.M-QS'!BT12,'Daily-DS.M-QS'!BR12,'Daily-DS.M-QS'!BP12,'Daily-DS.M-QS'!BN12,'Daily-DS.M-QS'!BL12) -> 0.2919213 | E12: =AVERAGE('Daily-DS.M-QS'!DS12,'Daily-DS.M-QS'!DQ12,'Daily-DS.M-QS'!DO12,'Daily-DS.M-QS'!DM12,'Daily-DS.M-QS'!DK12,'Daily-DS.M-QS'!DI12,'Daily-DS.M-QS'!DG12,'Daily-DS.M-QS'!DE12,'Daily-DS.M-QS'!DC12,'Daily-DS.M-QS'!DA12,'Daily-DS.M-QS'!CY12,'Daily-DS.M-QS'!CW12,'Daily-DS.M-QS'!CU12,'Daily-DS.M-QS'!CS12,'Daily-DS.M-QS'!CQ12,'Daily-DS.M-QS'!CO12,'Daily-DS.M-QS'!CM12,'Daily-DS.M-QS'!CK12,'Daily-DS.M-QS'!CI12,'Daily-DS.M-QS'!CG12,'Daily-DS.M-QS'!CE12,'Daily-DS.M-QS'!CC12,'Daily-DS.M-QS'!CA12,'Daily-DS.M-QS'!BY12,'Daily-DS.M-QS'!BW12,'Daily-DS.M-QS'!BU12,'Daily-DS.M-QS'!BS12,'Daily-DS.M-QS'!BQ12,'Daily-DS.M-QS'!BO12,'Daily-DS.M-QS'!BM12) -> 0.22900463
A14: Appels courts < 15s | B14: ='Daily-DS.M-QS'!BJ14+'Daily-DS.M-QS'!BH14+'Daily-DS.M-QS'!BF14+'Daily-DS.M-QS'!BD14+'Daily-DS.M-QS'!BB14+'Daily-DS.M-QS'!AZ14+'Daily-DS.M-QS'!AX14+'Daily-DS.M-QS'!AV14+'Daily-DS.M-QS'!AT14+'Daily-DS.M-QS'!AR14+'Daily-DS.M-QS'!AP14+'Daily-DS.M-QS'!AN14+'Daily-DS.M-QS'!AL14+'Daily-DS.M-QS'!AJ14+'Daily-DS.M-QS'!AH14+'Daily-DS.M-QS'!AF14+'Daily-DS.M-QS'!AD14+'Daily-DS.M-QS'!AB14+'Daily-DS.M-QS'!Z14+'Daily-DS.M-QS'!X14+'Daily-DS.M-QS'!V14+'Daily-DS.M-QS'!T14+'Daily-DS.M-QS'!R14+'Daily-DS.M-QS'!P14+'Daily-DS.M-QS'!N14+'Daily-DS.M-QS'!L14+'Daily-DS.M-QS'!J14+'Daily-DS.M-QS'!H14+'Daily-DS.M-QS'!F14+'Daily-DS.M-QS'!D14+'Daily-DS.M-QS'!B14 -> 97 | C14: ='Daily-DS.M-QS'!BK14+'Daily-DS.M-QS'!BI14+'Daily-DS.M-QS'!BG14+'Daily-DS.M-QS'!BE14+'Daily-DS.M-QS'!BC14+'Daily-DS.M-QS'!BA14+'Daily-DS.M-QS'!AY14+'Daily-DS.M-QS'!AW14+'Daily-DS.M-QS'!AU14+'Daily-DS.M-QS'!AS14+'Daily-DS.M-QS'!AQ14+'Daily-DS.M-QS'!AO14+'Daily-DS.M-QS'!AM14+'Daily-DS.M-QS'!AK14+'Daily-DS.M-QS'!AI14+'Daily-DS.M-QS'!AG14+'Daily-DS.M-QS'!AE14+'Daily-DS.M-QS'!AC14+'Daily-DS.M-QS'!AA14+'Daily-DS.M-QS'!Y14+'Daily-DS.M-QS'!W14+'Daily-DS.M-QS'!U14+'Daily-DS.M-QS'!S14+'Daily-DS.M-QS'!Q14+'Daily-DS.M-QS'!O14+'Daily-DS.M-QS'!M14+'Daily-DS.M-QS'!K14+'Daily-DS.M-QS'!I14+'Daily-DS.M-QS'!G14+'Daily-DS.M-QS'!E14+'Daily-DS.M-QS'!C14 -> 90 | D14: ='Daily-DS.M-QS'!DR14+'Daily-DS.M-QS'!DP14+'Daily-DS.M-QS'!DN14+'Daily-DS.M-QS'!DL14+'Daily-DS.M-QS'!DJ14+'Daily-DS.M-QS'!DH14+'Daily-DS.M-QS'!DF14+'Daily-DS.M-QS'!DD14+'Daily-DS.M-QS'!DB14+'Daily-DS.M-QS'!CZ14+'Daily-DS.M-QS'!CX14+'Daily-DS.M-QS'!CV14+'Daily-DS.M-QS'!CT14+'Daily-DS.M-QS'!CR14+'Daily-DS.M-QS'!CP14+'Daily-DS.M-QS'!CN14+'Daily-DS.M-QS'!CL14+'Daily-DS.M-QS'!CJ14+'Daily-DS.M-QS'!CH14+'Daily-DS.M-QS'!CF14+'Daily-DS.M-QS'!CD14+'Daily-DS.M-QS'!CB14+'Daily-DS.M-QS'!BZ14+'Daily-DS.M-QS'!BX14+'Daily-DS.M-QS'!BV14+'Daily-DS.M-QS'!BT14+'Daily-DS.M-QS'!BR14+'Daily-DS.M-QS'!BP14+'Daily-DS.M-QS'!BN14+'Daily-DS.M-QS'!BL14 -> 193 | E14: ='Daily-DS.M-QS'!DS14+'Daily-DS.M-QS'!DQ14+'Daily-DS.M-QS'!DO14+'Daily-DS.M-QS'!DM14+'Daily-DS.M-QS'!DK14+'Daily-DS.M-QS'!DI14+'Daily-DS.M-QS'!DG14+'Daily-DS.M-QS'!DE14+'Daily-DS.M-QS'!DC14+'Daily-DS.M-QS'!DA14+'Daily-DS.M-QS'!CY14+'Daily-DS.M-QS'!CW14+'Daily-DS.M-QS'!CU14+'Daily-DS.M-QS'!CS14+'Daily-DS.M-QS'!CQ14+'Daily-DS.M-QS'!CO14+'Daily-DS.M-QS'!CM14+'Daily-DS.M-QS'!CK14+'Daily-DS.M-QS'!CI14+'Daily-DS.M-QS'!CG14+'Daily-DS.M-QS'!CE14+'Daily-DS.M-QS'!CC14+'Daily-DS.M-QS'!CA14+'Daily-DS.M-QS'!BY14+'Daily-DS.M-QS'!BW14+'Daily-DS.M-QS'!BU14+'Daily-DS.M-QS'!BS14+'Daily-DS.M-QS'!BQ14+'Daily-DS.M-QS'!BO14+'Daily-DS.M-QS'!BM14 -> 115
A15: Taux de conformité | B15: =B14/B4 -> 0.063192182 | C15: =C14/C4 -> 0.075821398 | D15: =D14/D4 -> 0.066620642 | E15: =E14/E4 -> 0.066206102
A17: Appels Répondus <30s | B17: ='Daily-DS.M-QS'!BJ17+'Daily-DS.M-QS'!BH17+'Daily-DS.M-QS'!BF17+'Daily-DS.M-QS'!BD17+'Daily-DS.M-QS'!BB17+'Daily-DS.M-QS'!AZ17+'Daily-DS.M-QS'!AX17+'Daily-DS.M-QS'!AV17+'Daily-DS.M-QS'!AT17+'Daily-DS.M-QS'!AR17+'Daily-DS.M-QS'!AP17+'Daily-DS.M-QS'!AN17+'Daily-DS.M-QS'!AL17+'Daily-DS.M-QS'!AJ17+'Daily-DS.M-QS'!AH17+'Daily-DS.M-QS'!AF17+'Daily-DS.M-QS'!AD17+'Daily-DS.M-QS'!AB17+'Daily-DS.M-QS'!Z17+'Daily-DS.M-QS'!X17+'Daily-DS.M-QS'!V17+'Daily-DS.M-QS'!T17+'Daily-DS.M-QS'!R17+'Daily-DS.M-QS'!P17+'Daily-DS.M-QS'!N17+'Daily-DS.M-QS'!L17+'Daily-DS.M-QS'!J17+'Daily-DS.M-QS'!H17+'Daily-DS.M-QS'!F17+'Daily-DS.M-QS'!D17+'Daily-DS.M-QS'!B17 -> 1259 | C17: ='Daily-DS.M-QS'!BK17+'Daily-DS.M-QS'!BI17+'Daily-DS.M-QS'!BG17+'Daily-DS.M-QS'!BE17+'Daily-DS.M-QS'!BC17+'Daily-DS.M-QS'!BA17+'Daily-DS.M-QS'!AY17+'Daily-DS.M-QS'!AW17+'Daily-DS.M-QS'!AU17+'Daily-DS.M-QS'!AS17+'Daily-DS.M-QS'!AQ17+'Daily-DS.M-QS'!AO17+'Daily-DS.M-QS'!AM17+'Daily-DS.M-QS'!AK17+'Daily-DS.M-QS'!AI17+'Daily-DS.M-QS'!AG17+'Daily-DS.M-QS'!AE17+'Daily-DS.M-QS'!AC17+'Daily-DS.M-QS'!AA17+'Daily-DS.M-QS'!Y17+'Daily-DS.M-QS'!W17+'Daily-DS.M-QS'!U17+'Daily-DS.M-QS'!S17+'Daily-DS.M-QS'!Q17+'Daily-DS.M-QS'!O17+'Daily-DS.M-QS'!M17+'Daily-DS.M-QS'!K17+'Daily-DS.M-QS'!I17+'Daily-DS.M-QS'!G17+'Daily-DS.M-QS'!E17+'Daily-DS.M-QS'!C17 -> 983 | D17: ='Daily-DS.M-QS'!DR17+'Daily-DS.M-QS'!DP17+'Daily-DS.M-QS'!DN17+'Daily-DS.M-QS'!DL17+'Daily-DS.M-QS'!DJ17+'Daily-DS.M-QS'!DH17+'Daily-DS.M-QS'!DF17+'Daily-DS.M-QS'!DD17+'Daily-DS.M-QS'!DB17+'Daily-DS.M-QS'!CZ17+'Daily-DS.M-QS'!CX17+'Daily-DS.M-QS'!CV17+'Daily-DS.M-QS'!CT17+'Daily-DS.M-QS'!CR17+'Daily-DS.M-QS'!CP17+'Daily-DS.M-QS'!CN17+'Daily-DS.M-QS'!CL17+'Daily-DS.M-QS'!CJ17+'Daily-DS.M-QS'!CH17+'Daily-DS.M-QS'!CF17+'Daily-DS.M-QS'!CD17+'Daily-DS.M-QS'!CB17+'Daily-DS.M-QS'!BZ17+'Daily-DS.M-QS'!BX17+'Daily-DS.M-QS'!BV17+'Daily-DS.M-QS'!BT17+'Daily-DS.M-QS'!BR17+'Daily-DS.M-QS'!BP17+'Daily-DS.M-QS'!BN17+'Daily-DS.M-QS'!BL17 -> 2236 | E17: ='Daily-DS.M-QS'!DS17+'Daily-DS.M-QS'!DQ17+'Daily-DS.M-QS'!DO17+'Daily-DS.M-QS'!DM17+'Daily-DS.M-QS'!DK17+'Daily-DS.M-QS'!DI17+'Daily-DS.M-QS'!DG17+'Daily-DS.M-QS'!DE17+'Daily-DS.M-QS'!DC17+'Daily-DS.M-QS'!DA17+'Daily-DS.M-QS'!CY17+'Daily-DS.M-QS'!CW17+'Daily-DS.M-QS'!CU17+'Daily-DS.M-QS'!CS17+'Daily-DS.M-QS'!CQ17+'Daily-DS.M-QS'!CO17+'Daily-DS.M-QS'!CM17+'Daily-DS.M-QS'!CK17+'Daily-DS.M-QS'!CI17+'Daily-DS.M-QS'!CG17+'Daily-DS.M-QS'!CE17+'Daily-DS.M-QS'!CC17+'Daily-DS.M-QS'!CA17+'Daily-DS.M-QS'!BY17+'Daily-DS.M-QS'!BW17+'Daily-DS.M-QS'!BU17+'Daily-DS.M-QS'!BS17+'Daily-DS.M-QS'!BQ17+'Daily-DS.M-QS'!BO17+'Daily-DS.M-QS'!BM17 -> 1516
A18: SLA (30s) | B18: =B17/B4 -> 0.82019544 | C18: =C17/C4 -> 0.82813816 | D18: =D17/D4 -> 0.77183293 | E18: =E17/E4 -> 0.87276914
A21: DS | B21: S50 | D21: S49 | F21: S48 | H21: S47 | J21: S46 | L21: S45 | N21: S44 | P21: S43
B22: Magasin FO | C22: Magasin BO | D22: Magasin FO | E22: Magasin BO | F22: Magasin FO | G22: Magasin BO | H22: Magasin FO | I22: Magasin BO | J22: Magasin FO | K22: Magasin BO | L22: Magasin FO | M22: Magasin BO | N22: Magasin FO | O22: Magasin BO | P22: Magasin FO | Q22: Magasin BO
A23: Appels comptabilisés | B23: ='Daily-DS.M-QS'!AJ3+'Daily-DS.M-QS'!AL3+'Daily-DS.M-QS'!AN3+'Daily-DS.M-QS'!AP3+'Daily-DS.M-QS'!AR3+'Daily-DS.M-QS'!AT3+'Daily-DS.M-QS'!AV3 -> 669 | C23: ='Daily-DS.M-QS'!AK3+'Daily-DS.M-QS'!AM3+'Daily-DS.M-QS'!AO3+'Daily-DS.M-QS'!AQ3+'Daily-DS.M-QS'!AS3+'Daily-DS.M-QS'!AU3+'Daily-DS.M-QS'!AW3 -> 457 | D23: ='Daily-DS.M-QS'!AX3+'Daily-DS.M-QS'!AZ3+'Daily-DS.M-QS'!BB3+'Daily-DS.M-QS'!BD3+'Daily-DS.M-QS'!BF3+'Daily-DS.M-QS'!BH3+'Daily-DS.M-QS'!BJ3 -> 650 | E23: ='Daily-DS.M-QS'!AY3+'Daily-DS.M-QS'!BA3+'Daily-DS.M-QS'!BC3+'Daily-DS.M-QS'!BE3+'Daily-DS.M-QS'!BG3+'Daily-DS.M-QS'!BI3+'Daily-DS.M-QS'!BK3 -> 583 | F23: ='Daily-DS.M-QS'!BL3+'Daily-DS.M-QS'!BN3+'Daily-DS.M-QS'!BP3+'Daily-DS.M-QS'!BR3+'Daily-DS.M-QS'!BT3+'Daily-DS.M-QS'!BV3+'Daily-DS.M-QS'!BX3 -> 799 | G23: ='Daily-DS.M-QS'!BM3+'Daily-DS.M-QS'!BO3+'Daily-DS.M-QS'!BQ3+'Daily-DS.M-QS'!BS3+'Daily-DS.M-QS'!BU3+'Daily-DS.M-QS'!BW3+'Daily-DS.M-QS'!BY3 -> 410 | H23: ='Daily-DS.M-QS'!BZ3+'Daily-DS.M-QS'!CB3+'Daily-DS.M-QS'!CD3+'Daily-DS.M-QS'!CF3+'Daily-DS.M-QS'!CH3+'Daily-DS.M-QS'!CJ3+'Daily-DS.M-QS'!CL3 -> 623 | I23: ='Daily-DS.M-QS'!CA3+'Daily-DS.M-QS'!CC3+'Daily-DS.M-QS'!CE3+'Daily-DS.M-QS'!CG3+'Daily-DS.M-QS'!CI3+'Daily-DS.M-QS'!CK3+'Daily-DS.M-QS'!CM3 -> 456 | J23: ='Daily-DS.M-QS'!CN3+'Daily-DS.M-QS'!CP3+'Daily-DS.M-QS'!CR3+'Daily-DS.M-QS'!CT3+'Daily-DS.M-QS'!CV3+'Daily-DS.M-QS'!CX3+'Daily-DS.M-QS'!CZ3 -> 762 | K23: ='Daily-DS.M-QS'!CO3+'Daily-DS.M-QS'!CQ3+'Daily-DS.M-QS'!CS3+'Daily-DS.M-QS'!CU3+'Daily-DS.M-QS'!CW3+'Daily-DS.M-QS'!CY3+'Daily-DS.M-QS'!DA3 -> 351 | L23: ='Daily-DS.M-QS'!DB3+'Daily-DS.M-QS'!DD3+'Daily-DS.M-QS'!DF3+'Daily-DS.M-QS'!DH3+'Daily-DS.M-QS'!DJ3+'Daily-DS.M-QS'!DL3+'Daily-DS.M-QS'!DN3 -> 757 | M23: ='Daily-DS.M-QS'!DC3+'Daily-DS.M-QS'!DE3+'Daily-DS.M-QS'!DG3+'Daily-DS.M-QS'!DI3+'Daily-DS.M-QS'!DK3+'Daily-DS.M-QS'!DM3+'Daily-DS.M-QS'!DO3 -> 496 | N23: 812 | O23: 642 | P23: 613 | Q23: 481
A24: Appels Répondus | B24: ='Daily-DS.M-QS'!AJ4+'Daily-DS.M-QS'!AL4+'Daily-DS.M-QS'!AN4+'Daily-DS.M-QS'!AP4+'Daily-DS.M-QS'!AR4+'Daily-DS.M-QS'!AT4+'Daily-DS.M-QS'!AV4 -> 648 | C24: ='Daily-DS.M-QS'!AK4+'Daily-DS.M-QS'!AM4+'Daily-DS.M-QS'!AO4+'Daily-DS.M-QS'!AQ4+'Daily-DS.M-QS'!AS4+'Daily-DS.M-QS'!AU4+'Daily-DS.M-QS'!AW4 -> 446 | D24: ='Daily-DS.M-QS'!AX4+'Daily-DS.M-QS'!AZ4+'Daily-DS.M-QS'!BB4+'Daily-DS.M-QS'!BD4+'Daily-DS.M-QS'!BF4+'Daily-DS.M-QS'!BH4+'Daily-DS.M-QS'!BJ4 -> 640 | E24: ='Daily-DS.M-QS'!AY4+'Daily-DS.M-QS'!BA4+'Daily-DS.M-QS'!BC4+'Daily-DS.M-QS'!BE4+'Daily-DS.M-QS'!BG4+'Daily-DS.M-QS'!BI4+'Daily-DS.M-QS'!BK4 -> 569 | F24: ='Daily-DS.M-QS'!BL4+'Daily-DS.M-QS'!BN4+'Daily-DS.M-QS'!BP4+'Daily-DS.M-QS'!BR4+'Daily-DS.M-QS'!BT4+'Daily-DS.M-QS'!BV4+'Daily-DS.M-QS'!BX4 -> 778 | G24: ='Daily-DS.M-QS'!BM4+'Daily-DS.M-QS'!BO4+'Daily-DS.M-QS'!BQ4+'Daily-DS.M-QS'!BS4+'Daily-DS.M-QS'!BU4+'Daily-DS.M-QS'!BW4+'Daily-DS.M-QS'!BY4 -> 395 | H24: ='Daily-DS.M-QS'!BZ4+'Daily-DS.M-QS'!CB4+'Daily-DS.M-QS'!CD4+'Daily-DS.M-QS'!CF4+'Daily-DS.M-QS'!CH4+'Daily-DS.M-QS'!CJ4+'Daily-DS.M-QS'!CL4 -> 607 | I24: ='Daily-DS.M-QS'!CA4+'Daily-DS.M-QS'!CC4+'Daily-DS.M-QS'!CE4+'Daily-DS.M-QS'!CG4+'Daily-DS.M-QS'!CI4+'Daily-DS.M-QS'!CK4+'Daily-DS.M-QS'!CM4 -> 451 | J24: ='Daily-DS.M-QS'!CN4+'Daily-DS.M-QS'!CP4+'Daily-DS.M-QS'!CR4+'Daily-DS.M-QS'!CT4+'Daily-DS.M-QS'!CV4+'Daily-DS.M-QS'!CX4+'Daily-DS.M-QS'!CZ4 -> 690 | K24: ='Daily-DS.M-QS'!CO4+'Daily-DS.M-QS'!CQ4+'Daily-DS.M-QS'!CS4+'Daily-DS.M-QS'!CU4+'Daily-DS.M-QS'!CW4+'Daily-DS.M-QS'!CY4+'Daily-DS.M-QS'!DA4 -> 351 | L24: ='Daily-DS.M-QS'!DB4+'Daily-DS.M-QS'!DD4+'Daily-DS.M-QS'!DF4+'Daily-DS.M-QS'!DH4+'Daily-DS.M-QS'!DJ4+'Daily-DS.M-QS'!DL4+'Daily-DS.M-QS'!DN4 -> 720 | M24: ='Daily-DS.M-QS'!DC4+'Daily-DS.M-QS'!DE4+'Daily-DS.M-QS'!DG4+'Daily-DS.M-QS'!DI4+'Daily-DS.M-QS'!DK4+'Daily-DS.M-QS'!DM4+'Daily-DS.M-QS'!DO4 -> 487 | N24: 704 | O24: 570 | P24: 579 | Q24: 473
A25: Appels Perdus | B25: ='Daily-DS.M-QS'!AJ5+'Daily-DS.M-QS'!AL5+'Daily-DS.M-QS'!AN5+'Daily-DS.M-QS'!AP5+'Daily-DS.M-QS'!AR5+'Daily-DS.M-QS'!AT5+'Daily-DS.M-QS'!AV5 -> 21 | C25: ='Daily-DS.M-QS'!AK5+'Daily-DS.M-QS'!AM5+'Daily-DS.M-QS'!AO5+'Daily-DS.M-QS'!AQ5+'Daily-DS.M-QS'!AS5+'Daily-DS.M-QS'!AU5+'Daily-DS.M-QS'!AW5 -> 11 | D25: ='Daily-DS.M-QS'!AX5+'Daily-DS.M-QS'!AZ5+'Daily-DS.M-QS'!BB5+'Daily-DS.M-QS'!BD5+'Daily-DS.M-QS'!BF5+'Daily-DS.M-QS'!BH5+'Daily-DS.M-QS'!BJ5 -> 10 | E25: ='Daily-DS.M-QS'!AY5+'Daily-DS.M-QS'!BA5+'Daily-DS.M-QS'!BC5+'Daily-DS.M-QS'!BE5+'Daily-DS.M-QS'!BG5+'Daily-DS.M-QS'!BI5+'Daily-DS.M-QS'!BK5 -> 14 | F25: ='Daily-DS.M-QS'!BL5+'Daily-DS.M-QS'!BN5+'Daily-DS.M-QS'!BP5+'Daily-DS.M-QS'!BR5+'Daily-DS.M-QS'!BT5+'Daily-DS.M-QS'!BV5+'Daily-DS.M-QS'!BX5 -> 21 | G25: ='Daily-DS.M-QS'!BM5+'Daily-DS.M-QS'!BO5+'Daily-DS.M-QS'!BQ5+'Daily-DS.M-QS'!BS5+'Daily-DS.M-QS'!BU5+'Daily-DS.M-QS'!BW5+'Daily-DS.M-QS'!BY5 -> 15 | H25: ='Daily-DS.M-QS'!BZ5+'Daily-DS.M-QS'!CB5+'Daily-DS.M-QS'!CD5+'Daily-DS.M-QS'!CF5+'Daily-DS.M-QS'!CH5+'Daily-DS.M-QS'!CJ5+'Daily-DS.M-QS'!CL5 -> 16 | I25: ='Daily-DS.M-QS'!CA5+'Daily-DS.M-QS'!CC5+'Daily-DS.M-QS'!CE5+'Daily-DS.M-QS'!CG5+'Daily-DS.M-QS'!CI5+'Daily-DS.M-QS'!CK5+'Daily-DS.M-QS'!CM5 -> 5 | J25: ='Daily-DS.M-QS'!CN5+'Daily-DS.M-QS'!CP5+'Daily-DS.M-QS'!CR5+'Daily-DS.M-QS'!CT5+'Daily-DS.M-QS'!CV5+'Daily-DS.M-QS'!CX5+'Daily-DS.M-QS'!CZ5 -> 72 | K25: ='Daily-DS.M-QS'!CO5+'Daily-DS.M-QS'!CQ5+'Daily-DS.M-QS'!CS5+'Daily-DS.M-QS'!CU5+'Daily-DS.M-QS'!CW5+'Daily-DS.M-QS'!CY5+'Daily-DS.M-QS'!DA5 -> 0 | L25: ='Daily-DS.M-QS'!DB5+'Daily-DS.M-QS'!DD5+'Daily-DS.M-QS'!DF5+'Daily-DS.M-QS'!DH5+'Daily-DS.M-QS'!DJ5+'Daily-DS.M-QS'!DL5+'Daily-DS.M-QS'!DN5 -> 37 | M25: ='Daily-DS.M-QS'!DC5+'Daily-DS.M-QS'!DE5+'Daily-DS.M-QS'!DG5+'Daily-DS.M-QS'!DI5+'Daily-DS.M-QS'!DK5+'Daily-DS.M-QS'!DM5+'Daily-DS.M-QS'!DO5 -> 9 | N25: 108 | O25: 72 | P25: 34 | Q25: 8
A26: Appels Abandonnés | B26: ='Daily-DS.M-QS'!AJ6+'Daily-DS.M-QS'!AL6+'Daily-DS.M-QS'!AN6+'Daily-DS.M-QS'!AP6+'Daily-DS.M-QS'!AR6+'Daily-DS.M-QS'!AT6+'Daily-DS.M-QS'!AV6 -> 10 | C26: ='Daily-DS.M-QS'!AK6+'Daily-DS.M-QS'!AM6+'Daily-DS.M-QS'!AO6+'Daily-DS.M-QS'!AQ6+'Daily-DS.M-QS'!AS6+'Daily-DS.M-QS'!AU6+'Daily-DS.M-QS'!AW6 -> 7 | D26: ='Daily-DS.M-QS'!AX6+'Daily-DS.M-QS'!AZ6+'Daily-DS.M-QS'!BB6+'Daily-DS.M-QS'!BD6+'Daily-DS.M-QS'!BF6+'Daily-DS.M-QS'!BH6+'Daily-DS.M-QS'!BJ6 -> 3 | E26: ='Daily-DS.M-QS'!AY6+'Daily-DS.M-QS'!BA6+'Daily-DS.M-QS'!BC6+'Daily-DS.M-QS'!BE6+'Daily-DS.M-QS'!BG6+'Daily-DS.M-QS'!BI6+'Daily-DS.M-QS'!BK6 -> 2 | F26: ='Daily-DS.M-QS'!BL6+'Daily-DS.M-QS'!BN6+'Daily-DS.M-QS'!BP6+'Daily-DS.M-QS'!BR6+'Daily-DS.M-QS'!BT6+'Daily-DS.M-QS'!BV6+'Daily-DS.M-QS'!BX6 -> 7 | G26: ='Daily-DS.M-QS'!BM6+'Daily-DS.M-QS'!BO6+'Daily-DS.M-QS'!BQ6+'Daily-DS.M-QS'!BS6+'Daily-DS.M-QS'!BU6+'Daily-DS.M-QS'!BW6+'Daily-DS.M-QS'!BY6 -> 7 | H26: ='Daily-DS.M-QS'!BZ6+'Daily-DS.M-QS'!CB6+'Daily-DS.M-QS'!CD6+'Daily-DS.M-QS'!CF6+'Daily-DS.M-QS'!CH6+'Daily-DS.M-QS'!CJ6+'Daily-DS.M-QS'!CL6 -> 2 | I26: ='Daily-DS.M-QS'!CA6+'Daily-DS.M-QS'!CC6+'Daily-DS.M-QS'!CE6+'Daily-DS.M-QS'!CG6+'Daily-DS.M-QS'!CI6+'Daily-DS.M-QS'!CK6+'Daily-DS.M-QS'!CM6 -> 8 | J26: ='Daily-DS.M-QS'!CN6+'Daily-DS.M-QS'!CP6+'Daily-DS.M-QS'!CR6+'Daily-DS.M-QS'!CT6+'Daily-DS.M-QS'!CV6+'Daily-DS.M-QS'!CX6+'Daily-DS.M-QS'!CZ6 -> 57 | K26: ='Daily-DS.M-QS'!CO6+'Daily-DS.M-QS'!CQ6+'Daily-DS.M-QS'!CS6+'Daily-DS.M-QS'!CU6+'Daily-DS.M-QS'!CW6+'Daily-DS.M-QS'!CY6+'Daily-DS.M-QS'!DA6 -> 2 | L26: ='Daily-DS.M-QS'!DB6+'Daily-DS.M-QS'!DD6+'Daily-DS.M-QS'!DF6+'Daily-DS.M-QS'!DH6+'Daily-DS.M-QS'!DJ6+'Daily-DS.M-QS'!DL6+'Daily-DS.M-QS'!DN6 -> 26 | M26: ='Daily-DS.M-QS'!DC6+'Daily-DS.M-QS'!DE6+'Daily-DS.M-QS'!DG6+'Daily-DS.M-QS'!DI6+'Daily-DS.M-QS'!DK6+'Daily-DS.M-QS'!DM6+'Daily-DS.M-QS'!DO6 -> 7 | N26: 15 | O26: 16 | P26: 11 | Q26: 8
A27: QS | B27: =B24/B23 -> 0.96860987 | C27: =C24/C23 -> 0.97592998 | D27: =D24/D23 -> 0.98461538 | E27: =E24/E23 -> 0.97598628 | F27: =F24/F23 -> 0.97371715 | G27: =G24/G23 -> 0.96341463 | H27: =H24/H23 -> 0.97431782 | I27: =I24/I23 -> 0.98903509 | ... K27: =K24/K23 -> 1 | L27: 0.95 | M27: 0.98 | N27: 0.867 | O27: 0.8879 | P27: 0.9445 | Q27: 0.9834
A28: Taux des perdus | B28: =B25/B23 -> 0.031390135 | C28: =C26/C23 -> 0.015317287 | D28: =D25/D23 -> 0.015384615 | E28: =E26/E23 -> 0.0034305317 | F28: =F25/F23 -> 0.026282854 | G28: =G26/G23 -> 0.017073171 | H28: =H25/H23 -> 0.025682183 | I28: =I26/I23 -> 0.01754386 | J28: =J25/J23 -> 0.094488189 | K28: =K26/K23 -> 0.0056980057 | L28: 0.05 | M28: 0.02 | N28: 0.133 | O28: 0.1121 | P28: 0.0555 | Q28: 0.0166
A29: Taux des abandonnés | B29: =B26/B23 -> 0.014947683 | C29: =C26/C23 -> 0.015317287 | D29: =D26/D23 -> 0.0046153846 | E29: =E26/E23 -> 0.0034305317 | F29: =F26/F23 -> 0.0087609512 | G29: =G26/G23 -> 0.017073171 | H29: =H26/H23 -> 0.0032102729 | I29: =I26/I23 -> 0.01754386 | ... M29: =M26/M23 -> 0.014112903 | N29: 1,85% | O29: 2,49% | P29: 1,79% | Q29: 1,66%
A31: Durée Moy. d'attente | B31: =AVERAGE('Daily-DS.M-QS'!AJ11,'Daily-DS.M-QS'!AL11,'Daily-DS.M-QS'!AN11,'Daily-DS.M-QS'!AP11,'Daily-DS.M-QS'!AR11,'Daily-DS.M-QS'!AT11,'Daily-DS.M-QS'!AV11) -> 0.021130952 | C31: =AVERAGE('Daily-DS.M-QS'!AK11,'Daily-DS.M-QS'!AM11,'Daily-DS.M-QS'!AO11,'Daily-DS.M-QS'!AQ11,'Daily-DS.M-QS'!AS11,'Daily-DS.M-QS'!AU11,'Daily-DS.M-QS'!AW11) -> 0.025992063 | D31: =AVERAGE('Daily-DS.M-QS'!AX11,'Daily-DS.M-QS'!AZ11,'Daily-DS.M-QS'!BB11,'Daily-DS.M-QS'!BD11,'Daily-DS.M-QS'!BF11,'Daily-DS.M-QS'!BH11,'Daily-DS.M-QS'!BJ11) -> 0.016666667 | E31: =AVERAGE('Daily-DS.M-QS'!AY11,'Daily-DS.M-QS'!BA11,'Daily-DS.M-QS'!BC11,'Daily-DS.M-QS'!BE11,'Daily-DS.M-QS'!BG11,'Daily-DS.M-QS'!BI11,'Daily-DS.M-QS'!BK11) -> 0.015674603 | F31: =AVERAGE('Daily-DS.M-QS'!BL11,'Daily-DS.M-QS'!BN11,'Daily-DS.M-QS'!BP11,'Daily-DS.M-QS'!BR11,'Daily-DS.M-QS'!BT11,'Daily-DS.M-QS'!BV11,'Daily-DS.M-QS'!BX11) -> 0.022619048 | G31: =AVERAGE('Daily-DS.M-QS'!BM11,'Daily-DS.M-QS'!BO11,'Daily-DS.M-QS'!BQ11,'Daily-DS.M-QS'!BS11,'Daily-DS.M-QS'!BU11,'Daily-DS.M-QS'!BW11,'Daily-DS.M-QS'!BY11) -> 0.018551587 | H31: =AVERAGE('Daily-DS.M-QS'!BZ11,'Daily-DS.M-QS'!CB11,'Daily-DS.M-QS'!CD11,'Daily-DS.M-QS'!CF11,'Daily-DS.M-QS'!CH11,'Daily-DS.M-QS'!CJ11,'Daily-DS.M-QS'!CL11) -> 0.022718254 | I31: =AVERAGE('Daily-DS.M-QS'!CA11,'Daily-DS.M-QS'!CC11,'Daily-DS.M-QS'!CE11,'Daily-DS.M-QS'!CG11,'Daily-DS.M-QS'!CI11,'Daily-DS.M-QS'!CK11,'Daily-DS.M-QS'!CM11) -> 0.014583333 | J31: =AVERAGE('Daily-DS.M-QS'!CN11,'Daily-DS.M-QS'!CP11,'Daily-DS.M-QS'!CR11,'Daily-DS.M-QS'!CT11,'Daily-DS.M-QS'!CV11,'Daily-DS.M-QS'!CX11,'Daily-DS.M-QS'!CZ11) -> 0.022420635 | K31: =AVERAGE('Daily-DS.M-QS'!CO11,'Daily-DS.M-QS'!CQ11,'Daily-DS.M-QS'!CS11,'Daily-DS.M-QS'!CU11,'Daily-DS.M-QS'!CW11,'Daily-DS.M-QS'!CY11,'Daily-DS.M-QS'!DA11) -> 0.012301587 | L31: =AVERAGE('Daily-DS.M-QS'!DB11,'Daily-DS.M-QS'!DD11,'Daily-DS.M-QS'!DF11,'Daily-DS.M-QS'!DH11,'Daily-DS.M-QS'!DJ11,'Daily-DS.M-QS'!DL11,'Daily-DS.M-QS'!DN11) -> 0.034126984 | M31: =AVERAGE('Daily-DS.M-QS'!DC11,'Daily-DS.M-QS'!DE11,'Daily-DS.M-QS'!DG11,'Daily-DS.M-QS'!DI11,'Daily-DS.M-QS'!DK11,'Daily-DS.M-QS'!DM11,'Daily-DS.M-QS'!DO11) -> 0.019742063 | N31: 0.063888889 | O31: 0.013194444 | P31: 0.035416667 | Q31: 0.01875
A32: Durée Moy. de communication | B32: =AVERAGE('Daily-DS.M-QS'!AJ12,'Daily-DS.M-QS'!AL12,'Daily-DS.M-QS'!AN12,'Daily-DS.M-QS'!AP12,'Daily-DS.M-QS'!AR12,'Daily-DS.M-QS'!AT12,'Daily-DS.M-QS'!AV12) -> 0.28025794 | C32: =AVERAGE('Daily-DS.M-QS'!AK12,'Daily-DS.M-QS'!AM12,'Daily-DS.M-QS'!AO12,'Daily-DS.M-QS'!AQ12,'Daily-DS.M-QS'!AS12,'Daily-DS.M-QS'!AU12,'Daily-DS.M-QS'!AW12) -> 0.1781746 | D32: =AVERAGE('Daily-DS.M-QS'!AX12,'Daily-DS.M-QS'!AZ12,'Daily-DS.M-QS'!BB12,'Daily-DS.M-QS'!BD12,'Daily-DS.M-QS'!BF12,'Daily-DS.M-QS'!BH12,'Daily-DS.M-QS'!BJ12) -> 0.30486111 | E32: =AVERAGE('Daily-DS.M-QS'!AY12,'Daily-DS.M-QS'!BA12,'Daily-DS.M-QS'!BC12,'Daily-DS.M-QS'!BE12,'Daily-DS.M-QS'!BG12,'Daily-DS.M-QS'!BI12,'Daily-DS.M-QS'!BK12) -> 0.20168651 | F32: =AVERAGE('Daily-DS.M-QS'!BL12,'Daily-DS.M-QS'!BN12,'Daily-DS.M-QS'!BP12,'Daily-DS.M-QS'!BR12,'Daily-DS.M-QS'!BT12,'Daily-DS.M-QS'!BV12,'Daily-DS.M-QS'!BX12) -> 0.26458333 | G32: =AVERAGE('Daily-DS.M-QS'!BM12,'Daily-DS.M-QS'!BO12,'Daily-DS.M-QS'!BQ12,'Daily-DS.M-QS'!BS12,'Daily-DS.M-QS'!BU12,'Daily-DS.M-QS'!BW12,'Daily-DS.M-QS'!BY12) -> 0.17797619 | H32: =AVERAGE('Daily-DS.M-QS'!BZ12,'Daily-DS.M-QS'!CB12,'Daily-DS.M-QS'!CD12,'Daily-DS.M-QS'!CF12,'Daily-DS.M-QS'!CH12,'Daily-DS.M-QS'!CJ12,'Daily-DS.M-QS'!CL12) -> 0.2860119 | I32: =AVERAGE('Daily-DS.M-QS'!CA12,'Daily-DS.M-QS'!CC12,'Daily-DS.M-QS'!CE12,'Daily-DS.M-QS'!CG12,'Daily-DS.M-QS'!CI12,'Daily-DS.M-QS'!CK12,'Daily-DS.M-QS'!CM12) -> 0.23392857 | J32: =AVERAGE('Daily-DS.M-QS'!CN12,'Daily-DS.M-QS'!CP12,'Daily-DS.M-QS'!CR12,'Daily-DS.M-QS'!CT12,'Daily-DS.M-QS'!CV12,'Daily-DS.M-QS'!CX12,'Daily-DS.M-QS'!CZ12) -> 0.29206349 | K32: =AVERAGE('Daily-DS.M-QS'!CO12,'Daily-DS.M-QS'!CQ12,'Daily-DS.M-QS'!CS12,'Daily-DS.M-QS'!CU12,'Daily-DS.M-QS'!CW12,'Daily-DS.M-QS'!CY12,'Daily-DS.M-QS'!DA12) -> 0.26765873 | L32: =AVERAGE('Daily-DS.M-QS'!DB12,'Daily-DS.M-QS'!DD12,'Daily-DS.M-QS'!DF12,'Daily-DS.M-QS'!DH12,'Daily-DS.M-QS'!DJ12,'Daily-DS.M-QS'!DL12,'Daily-DS.M-QS'!DN12) -> 0.32202381 | M32: =AVERAGE('Daily-DS.M-QS'!DC12,'Daily-DS.M-QS'!DE12,'Daily-DS.M-QS'!DG12,'Daily-DS.M-QS'!DI12,'Daily-DS.M-QS'!DK12,'Daily-DS.M-QS'!DM12,'Daily-DS.M-QS'!DO12) -> 0.21418651 | N32: 0.30277778 | O32: 0.22222222 | P32: 0.32152778 | Q32: 0.18680556
A34: Appels courts < 15s | B34: ='Daily-DS.M-QS'!AJ14+'Daily-DS.M-QS'!AL14+'Daily-DS.M-QS'!AN14+'Daily-DS.M-QS'!AP14+'Daily-DS.M-QS'!AR14+'Daily-DS.M-QS'!AT14+'Daily-DS.M-QS'!AV14 -> 42 | C34: ='Daily-DS.M-QS'!AK14+'Daily-DS.M-QS'!AM14+'Daily-DS.M-QS'!AO14+'Daily-DS.M-QS'!AQ14+'Daily-DS.M-QS'!AS14+'Daily-DS.M-QS'!AU14+'Daily-DS.M-QS'!AW14 -> 26 | D34: ='Daily-DS.M-QS'!AX14+'Daily-DS.M-QS'!AZ14+'Daily-DS.M-QS'!BB14+'Daily-DS.M-QS'!BD14+'Daily-DS.M-QS'!BF14+'Daily-DS.M-QS'!BH14+'Daily-DS.M-QS'!BJ14 -> 34 | E34: ='Daily-DS.M-QS'!AY14+'Daily-DS.M-QS'!BA14+'Daily-DS.M-QS'!BC14+'Daily-DS.M-QS'!BE14+'Daily-DS.M-QS'!BG14+'Daily-DS.M-QS'!BI14+'Daily-DS.M-QS'!BK14 -> 46 | F34: ='Daily-DS.M-QS'!BL14+'Daily-DS.M-QS'!BN14+'Daily-DS.M-QS'!BP14+'Daily-DS.M-QS'!BR14+'Daily-DS.M-QS'!BT14+'Daily-DS.M-QS'!BV14+'Daily-DS.M-QS'!BX14 -> 59 | G34: ='Daily-DS.M-QS'!BM14+'Daily-DS.M-QS'!BO14+'Daily-DS.M-QS'!BQ14+'Daily-DS.M-QS'!BS14+'Daily-DS.M-QS'!BU14+'Daily-DS.M-QS'!BW14+'Daily-DS.M-QS'!BY14 -> 38 | H34: ='Daily-DS.M-QS'!BZ14+'Daily-DS.M-QS'!CB14+'Daily-DS.M-QS'!CD14+'Daily-DS.M-QS'!CF14+'Daily-DS.M-QS'!CH14+'Daily-DS.M-QS'!CJ14+'Daily-DS.M-QS'!CL14 -> 51 | I34: ='Daily-DS.M-QS'!CA14+'Daily-DS.M-QS'!CC14+'Daily-DS.M-QS'!CE14+'Daily-DS.M-QS'!CG14+'Daily-DS.M-QS'!CI14+'Daily-DS.M-QS'!CK14+'Daily-DS.M-QS'!CM14 -> 21 | J34: ='Daily-DS.M-QS'!CN14+'Daily-DS.M-QS'!CP14+'Daily-DS.M-QS'!CR14+'Daily-DS.M-QS'!CT14+'Daily-DS.M-QS'!CV14+'Daily-DS.M-QS'!CX14+'Daily-DS.M-QS'!CZ14 -> 47 | K34: ='Daily-DS.M-QS'!CO14+'Daily-DS.M-QS'!CQ14+'Daily-DS.M-QS'!CS14+'Daily-DS.M-QS'!CU14+'Daily-DS.M-QS'!CW14+'Daily-DS.M-QS'!CY14+'Daily-DS.M-QS'!DA14 -> 20 | L34: ='Daily-DS.M-QS'!DB14+'Daily-DS.M-QS'!DD14+'Daily-DS.M-QS'!DF14+'Daily-DS.M-QS'!DH14+'Daily-DS.M-QS'!DJ14+'Daily-DS.M-QS'!DL14+'Daily-DS.M-QS'!DN14 -> 32 | M34: ='Daily-DS.M-QS'!DC14+'Daily-DS.M-QS'!DE14+'Daily-DS.M-QS'!DG14+'Daily-DS.M-QS'!DI14+'Daily-DS.M-QS'!DK14+'Daily-DS.M-QS'!DM14+'Daily-DS.M-QS'!DO14 -> 33 | N34: 24 | O34: 29 | P34: 26 | Q34: 28
A35: Taux de conformité | B35: =B34/B24 -> 0.064814815 | C35: =C34/C24 -> 0.058295964 | D35: =D34/D24 -> 0.053125 | E35: =E34/E24 -> 0.080843585 | F35: =F34/F24 -> 0.075835476 | G35: =G34/G24 -> 0.096202532 | H35: =H34/H24 -> 0.084019769 | I35: =I34/I24 -> 0.046563193 | ... M35: =M34/M24 -> 0.067761807 | N35: 3,41% | O35: 5,09% | P35: 4,49% | Q35: 5,92%
A37: Appels Répondus <30s | B37: ='Daily-DS.M-QS'!AJ17+'Daily-DS.M-QS'!AL17+'Daily-DS.M-QS'!AN17+'Daily-DS.M-QS'!AP17+'Daily-DS.M-QS'!AR17+'Daily-DS.M-QS'!AT17+'Daily-DS.M-QS'!AV17 -> 535 | C37: ='Daily-DS.M-QS'!AK17+'Daily-DS.M-QS'!AM17+'Daily-DS.M-QS'!AO17+'Daily-DS.M-QS'!AQ17+'Daily-DS.M-QS'!AS17+'Daily-DS.M-QS'!AU17+'Daily-DS.M-QS'!AW17 -> 373 | D37: ='Daily-DS.M-QS'!AX17+'Daily-DS.M-QS'!AZ17+'Daily-DS.M-QS'!BB17+'Daily-DS.M-QS'!BD17+'Daily-DS.M-QS'!BF17+'Daily-DS.M-QS'!BH17+'Daily-DS.M-QS'!BJ17 -> 548 | E37: ='Daily-DS.M-QS'!AY17+'Daily-DS.M-QS'!BA17+'Daily-DS.M-QS'!BC17+'Daily-DS.M-QS'!BE17+'Daily-DS.M-QS'!BG17+'Daily-DS.M-QS'!BI17+'Daily-DS.M-QS'!BK17 -> 478 | F37: ='Daily-DS.M-QS'!BL17+'Daily-DS.M-QS'!BN17+'Daily-DS.M-QS'!BP17+'Daily-DS.M-QS'!BR17+'Daily-DS.M-QS'!BT17+'Daily-DS.M-QS'!BV17+'Daily-DS.M-QS'!BX17 -> 626 | G37: ='Daily-DS.M-QS'!BM17+'Daily-DS.M-QS'!BO17+'Daily-DS.M-QS'!BQ17+'Daily-DS.M-QS'!BS17+'Daily-DS.M-QS'!BU17+'Daily-DS.M-QS'!BW17+'Daily-DS.M-QS'!BY17 -> 338 | H37: ='Daily-DS.M-QS'!BZ17+'Daily-DS.M-QS'!CB17+'Daily-DS.M-QS'!CD17+'Daily-DS.M-QS'!CF17+'Daily-DS.M-QS'!CH17+'Daily-DS.M-QS'!CJ17+'Daily-DS.M-QS'!CL17 -> 479 | I37: ='Daily-DS.M-QS'!CA17+'Daily-DS.M-QS'!CC17+'Daily-DS.M-QS'!CE17+'Daily-DS.M-QS'!CG17+'Daily-DS.M-QS'!CI17+'Daily-DS.M-QS'!CK17+'Daily-DS.M-QS'!CM17 -> 403 | J37: ='Daily-DS.M-QS'!CN17+'Daily-DS.M-QS'!CP17+'Daily-DS.M-QS'!CR17+'Daily-DS.M-QS'!CT17+'Daily-DS.M-QS'!CV17+'Daily-DS.M-QS'!CX17+'Daily-DS.M-QS'!CZ17 -> 556 | K37: ='Daily-DS.M-QS'!CO17+'Daily-DS.M-QS'!CQ17+'Daily-DS.M-QS'!CS17+'Daily-DS.M-QS'!CU17+'Daily-DS.M-QS'!CW17+'Daily-DS.M-QS'!CY17+'Daily-DS.M-QS'!DA17 -> 313 | L37: ='Daily-DS.M-QS'!DB17+'Daily-DS.M-QS'!DD17+'Daily-DS.M-QS'!DF17+'Daily-DS.M-QS'!DH17+'Daily-DS.M-QS'!DJ17+'Daily-DS.M-QS'!DL17+'Daily-DS.M-QS'!DN17 -> 528 | M37: ='Daily-DS.M-QS'!DC17+'Daily-DS.M-QS'!DE17+'Daily-DS.M-QS'!DG17+'Daily-DS.M-QS'!DI17+'Daily-DS.M-QS'!DK17+'Daily-DS.M-QS'!DM17+'Daily-DS.M-QS'!DO17 -> 415 | N37: 469 | O37: 482 | P37: 443 | Q37: 398
A38: SLA (30s) | B38: =B37/B24 -> 0.82561728 | C38: =C37/C24 -> 0.83632287 | D38: =D37/D24 -> 0.85625 | E38: =E37/E24 -> 0.8400703 | F38: =F37/F24 -> 0.80462725 | G38: =G37/G24 -> 0.8556962 | H38: =H37/H24 -> 0.78912685 | I38: =I37/I24 -> 0.89356984 | ... M38: =M37/M24 -> 0.85215606 | N38: 66,62% | O38: 84,56% | P38: 76,51% | Q38: 84,14%

Sheet Daily-DS.M-QS
A1: DS | B1: 46022 | D1: 46021 | F1: 46020 | H1: 46019 | J1: 46018 | L1: 46017 | N1: 46016 | P1: 46015 | R1: 46014 | T1: 46013 | V1: 46012 | X1: 46011 | Z1: 46010 | AB1: 46009 | AD1: 46008 | AF1: 46007 | AH1: 46006 | AJ1: 46005 | AL1: 46004 | AN1: 46003 | AP1: 46002 | AR1: 46001 | AT1: 46000 | AV1: 45999 | AX1: 45998 | AZ1: 45997 | BB1: 45996 | BD1: 45995 | BF1: 45994 | BH1: 45993 | BJ1: 45992 | BL1: 45991 | BN1: 45990 | BP1: 45989 | BR1: 45988 | BT1: 45987 | BV1: 45986 | BX1: 45985 | BZ1: 45984 | CB1: 45983 | CD1: 45982 | CF1: 45981 | CH1: 45980 | CJ1: 45979 | CL1: 45978 | CN1: 45977 | CP1: 45976 | CR1: 45975 | CT1: 45974 | CV1: 45973 | CX1: 45972 | CZ1: 45971 | DB1: 45970 | DD1: 45969 | DF1: 45968 | DH1: 45967 | DJ1: 45966 | DL1: 45965 | DN1: 45964 | DP1: 45963 | DR1: 45962 | DT1: 45961 | DV1: 45960 | DX1: 45959 | DZ1: 45958 | EB1: 45957 | ED1: 45956 | EF1: 45955 | EH1: 45954 | EJ1: 45953 | EL1: 45952 | EN1: 45951 | EP1: 45950
B2: Magasin FO | C2: Magasin BO | D2: Magasin FO | E2: Magasin BO | F2: Magasin FO | G2: Magasin BO | H2: Magasin FO | I2: Magasin BO | J2: Magasin FO | K2: Magasin BO | L2: Magasin FO | M2: Magasin BO | N2: Magasin FO | O2: Magasin BO | P2: Magasin FO | Q2: Magasin BO | R2: Magasin FO | S2: Magasin BO | T2: Magasin FO | U2: Magasin BO | V2: Magasin FO | W2: Magasin BO | X2: Magasin FO | Y2: Magasin BO | Z2: Magasin FO | AA2: Magasin BO | AB2: Magasin FO | AC2: Magasin BO | AD2: Magasin FO | AE2: Magasin BO | AF2: Magasin FO | AG2: Magasin BO | AH2: Magasin FO | AI2: Magasin BO | AJ2: Magasin FO | AK2: Magasin BO | AL2: Magasin FO | AM2: Magasin BO | AN2: Magasin FO | AO2: Magasin BO | AP2: Magasin FO | AQ2: Magasin BO | AR2: Magasin FO | AS2: Magasin BO | AT2: Magasin FO | AU2: Magasin BO | AV2: Magasin FO | AW2: Magasin BO | AX2: Magasin FO | AY2: Magasin BO | AZ2: Magasin FO | BA2: Magasin BO | BB2: Magasin FO | BC2: Magasin BO | BD2: Magasin FO | BE2: Magasin BO | BF2: Magasin FO | BG2: Magasin BO | BH2: Magasin FO | BI2: Magasin BO | BJ2: Magasin FO | BK2: Magasin BO | BL2: Magasin FO | BM2: Magasin BO | BN2: Magasin FO | BO2: Magasin BO | BP2: Magasin FO | BQ2: Magasin BO | BR2: Magasin FO | BS2: Magasin BO | BT2: Magasin FO | BU2: Magasin BO | BV2: Magasin FO | BW2: Magasin BO | BX2: Magasin FO | BY2: Magasin BO | BZ2: Magasin FO | CA2: Magasin BO | CB2: Magasin FO | CC2: Magasin BO | CD2: Magasin FO | CE2: Magasin BO | CF2: Magasin FO | CG2: Magasin BO | CH2: Magasin FO | CI2: Magasin BO | CJ2: Magasin FO | CK2: Magasin BO | CL2: Magasin FO | CM2: Magasin BO | CN2: Magasin FO | CO2: Magasin BO | CP2: Magasin FO | CQ2: Magasin BO | CR2: Magasin FO | CS2: Magasin BO | CT2: Magasin FO | CU2: Magasin BO | CV2: Magasin FO | CW2: Magasin BO | CX2: Magasin FO | CY2: Magasin BO | CZ2: Magasin FO | DA2: Magasin BO | DB2: Magasin FO | DC2: Magasin BO | DD2: Magasin FO | DE2: Magasin BO | DF2: Magasin FO | DG2: Magasin BO | DH2: Magasin FO | DI2: Magasin BO | DJ2: Magasin FO | DK2: Magasin BO | DL2: Magasin FO | DM2: Magasin BO | DN2: Magasin FO | DO2: Magasin BO | DP2: Magasin FO | DQ2: Magasin BO | DR2: Magasin FO | DS2: Magasin BO | DT2: Magasin FO | DU2: Magasin BO | DV2: Magasin FO | DW2: Magasin BO | DX2: Magasin FO | DY2: Magasin BO | DZ2: Magasin FO | EA2: Magasin BO | EB2: Magasin FO | EC2: Magasin BO | ED2: Magasin FO | EE2: Magasin BO | EF2: Magasin FO | EG2: Magasin BO | EH2: Magasin FO | EI2: Magasin BO | EJ2: Magasin FO | EK2: Magasin BO | EL2: Magasin FO | EM2: Magasin BO | EN2: Magasin FO | EO2: Magasin BO | EP2: Magasin FO | EQ2: Magasin BO
A3: Appels comptabilisés | AF3: 117 | AG3: 71 | AH3: 138 | AI3: 108 | AJ3: 32 | AK3: 3 | AL3: 100 | AM3: 42 | AN3: 108 | AO3: 65 | AP3: 101 | AQ3: 85 | AR3: 104 | AS3: 86 | AT3: 114 | AU3: 97 | AV3: 110 | AW3: 79 | AX3: 35 | AY3: 4 | AZ3: 91 | BA3: 45 | BB3: 82 | BC3: 87 | BD3: 103 | BE3: 77 | BF3: 102 | BG3: 83 | BH3: 121 | BI3: 105 | BJ3: 116 | BK3: 182 | BL3: 41 | BM3: 6 | BN3: 136 | BO3: 53 | BP3: 133 | BQ3: 79 | BR3: 99 | BS3: 75 | BT3: 119 | BU3: 66 | BV3: 149 | BW3: 55 | BX3: 122 | BY3: 76 | BZ3: 29 | CA3: 4 | CB3: 119 | CC3: 38 | CD3: 112 | CE3: 77 | CF3: 82 | CG3: 94 | CH3: 101 | CI3: 81 | CJ3: 73 | CK3: 92 | CL3: 107 | CM3: 70 | CN3: 14 | CO3: 1 | CP3: 97 | CQ3: 40 | CR3: 104 | CS3: 82 | CT3: 146 | CU3: 67 | CV3: 122 | CW3: 80 | CX3: 49 | CY3: 22 | CZ3: 230 | DA3: 59 | DB3: 19 | DC3: 8 | DD3: 99 | DE3: 24 | DF3: 99 | DG3: 59 | DH3: 130 | DI3: 81 | DJ3: 116 | DK3: 82 | DL3: 155 | DM3: 106 | DN3: 139 | DO3: 136 | DP3: 21 | DQ3: 1 | DR3: 135 | DS3: 53 | DT3: 164 | DU3: 173 | DV3: 153 | DW3: 100 | DX3: 133 | DY3: 165 | DZ3: 91 | EA3: 84 | EB3: 115 | EC3: 66 | ED3: 24 | EE3: 9 | EF3: 74 | EG3: 68 | EH3: 110 | EI3: 62 | EJ3: 116 | EK3: 91 | EL3: 138 | EM3: 56 | EN3: 70 | EO3: 104 | EP3: 81 | EQ3: 91
A4: Appels Répondus | AF4: 114 | AG4: 71 | AH4: 133 | AI4: 101 | AJ4: 28 | AK4: 3 | AL4: 97 | AM4: 40 | AN4: 105 | AO4: 63 | AP4: 99 | AQ4: 82 | AR4: 99 | AS4: 84 | AT4: 111 | AU4: 96 | AV4: 109 | AW4: 78 | AX4: 34 | AY4: 4 | AZ4: 88 | BA4: 44 | BB4: 81 | BC4: 87 | BD4: 102 | BE4: 76 | BF4: 102 | BG4: 83 | BH4: 118 | BI4: 104 | BJ4: 115 | BK4: 171 | BL4: 35 | BM4: 1 | BN4: 132 | BO4: 53 | BP4: 133 | BQ4: 74 | BR4: 99 | BS4: 75 | BT4: 117 | BU4: 66 | BV4: 142 | BW4: 50 | BX4: 120 | BY4: 76 | BZ4: 29 | CA4: 4 | CB4: 112 | CC4: 38 | CD4: 112 | CE4: 77 | CF4: 82 | CG4: 94 | CH4: 101 | CI4: 81 | CJ4: 72 | CK4: 91 | CL4: 99 | CM4: 66 | CN4: 12 | CO4: 1 | CP4: 90 | CQ4: 40 | CR4: 101 | CS4: 82 | CT4: 142 | CU4: 67 | CV4: 120 | CW4: 80 | CX4: 48 | CY4: 22 | CZ4: 177 | DA4: 59 | DB4: 19 | DC4: 7 | DD4: 93 | DE4: 24 | DF4: 98 | DG4: 59 | DH4: 124 | DI4: 80 | DJ4: 114 | DK4: 82 | DL4: 148 | DM4: 99 | DN4: 124 | DO4: 136 | DP4: 17 | DQ4: 1 | DR4: 85 | DS4: 52 | DT4: 135 | DU4: 110 | DV4: 143 | DW4: 99 | DX4: 124 | DY4: 165 | DZ4: 88 | EA4: 84 | EB4: 112 | EC4: 59 | ED4: 20 | EE4: 9 | EF4: 70 | EG4: 65 | EH4: 105 | EI4: 62 | EJ4: 111 | EK4: 89 | EL4: 133 | EM4: 55 | EN4: 63 | EO4: 102 | EP4: 77 | EQ4: 91
A5: Appels Perdus | AF5: 3 | AG5: 0 | AH5: 5 | AI5: 7 | AJ5: 4 | AK5: 0 | AL5: 3 | AM5: 2 | AN5: 3 | AO5: 2 | AP5: 2 | AQ5: 3 | AR5: 5 | AS5: 2 | AT5: 3 | AU5: 1 | AV5: 1 | AW5: 1 | AX5: 1 | AY5: 0 | AZ5: 3 | BA5: 1 | BB5: 1 | BC5: 0 | BD5: 1 | BE5: 1 | BF5: 0 | BG5: 0 | BH5: 3 | BI5: 1 | BJ5: 1 | BK5: 11 | BL5: 6 | BM5: 5 | BN5: 4 | BO5: 0 | BP5: 0 | BQ5: 5 | BR5: 0 | BS5: 0 | BT5: 2 | BU5: 0 | BV5: 7 | BW5: 5 | BX5: 2 | BY5: 0 | BZ5: 0 | CA5: 0 | CB5: 7 | CC5: 0 | CD5: 0 | CE5: 0 | CF5: 0 | CG5: 0 | CH5: 0 | CI5: 0 | CJ5: 1 | CK5: 1 | CL5: 8 | CM5: 4 | CN5: 2 | CO5: 0 | CP5: 7 | CQ5: 0 | CR5: 3 | CS5: 0 | CT5: 4 | CU5: 0 | CV5: 2 | CW5: 0 | CX5: 1 | CY5: 0 | CZ5: 53 | DA5: 0 | DB5: 0 | DC5: 1 | DD5: 6 | DE5: 0 | DF5: 1 | DG5: 0 | DH5: 6 | DI5: 1 | DJ5: 2 | DK5: 0 | DL5: 7 | DM5: 7 | DN5: 15 | DO5: 0 | DP5: 4 | DQ5: 0 | DR5: 50 | DS5: 1 | DT5: 29 | DU5: 63 | DV5: 10 | DW5: 1 | DX5: 9 | DY5: 0 | DZ5: 3 | EA5: 0 | EB5: 3 | EC5: 7 | ED5: 4 | EE5: 0 | EF5: 4 | EG5: 3 | EH5: 5 | EI5: 0 | EJ5: 5 | EK5: 2 | EL5: 5 | EM5: 1 | EN5: 7 | EO5: 2 | EP5: 4 | EQ5: 0
A6: Appels Abandonnés | AF6: 0 | AG6: 1 | AH6: 3 | AI6: 4 | AJ6: 0 | AK6: 0 | AL6: 1 | AM6: 0 | AN6: 2 | AO6: 0 | AP6: 2 | AQ6: 4 | AR6: 1 | AS6: 0 | AT6: 1 | AU6: 2 | AV6: 3 | AW6: 1 | AX6: 0 | AY6: 0 | AZ6: 0 | BA6: 0 | BB6: 2 | BC6: 1 | BD6: 0 | BE6: 0 | BF6: 0 | BG6: 1 | BH6: 0 | BI6: 0 | BJ6: 1 | BK6: 0 | BL6: 0 | BM6: 0 | BN6: 1 | BO6: 0 | BP6: 1 | BQ6: 0 | BR6: 0 | BS6: 4 | BT6: 0 | BU6: 1 | BV6: 3 | BW6: 0 | BX6: 2 | BY6: 2 | BZ6: 0 | CA6: 0 | CB6: 1 | CC6: 0 | CD6: 0 | CE6: 1 | CF6: 0 | CG6: 4 | CH6: 0 | CI6: 0 | CJ6: 1 | CK6: 2 | CL6: 0 | CM6: 1 | CN6: 0 | CO6: 0 | CP6: 2 | CQ6: 0 | CR6: 0 | CS6: 1 | CT6: 2 | CU6: 1 | CV6: 3 | CW6: 0 | CX6: 1 | CY6: 0 | CZ6: 49 | DA6: 0 | DB6: 0 | DC6: 0 | DD6: 1 | DE6: 0 | DF6: 1 | DG6: 2 | DH6: 8 | DI6: 0 | DJ6: 1 | DK6: 3 | DL6: 8 | DM6: 2 | DN6: 7 | DO6: 0 | DP6: 0 | DQ6: 0 | DR6: 7 | DS6: 1 | DT6: 2 | DU6: 11 | DV6: 1 | DW6: 0 | DX6: 1 | DY6: 0 | DZ6: 3 | EA6: 2 | EB6: 1 | EC6: 2 | ED6: 1 | EE6: 0 | EF6: 0 | EG6: 1 | EH6: 2 | EI6: 0 | EJ6: 1 | EK6: 2 | EL6: 4 | EM6: 3 | EN6: 2 | EO6: 2 | EP6: 1 | EQ6: 0
A7: Taux de décroché | AF7: 0.97 | AG7: 1 | AH7: 0.96 | AI7: 0.935 | AJ7: 0.88 | AK7: 1 | AL7: 0.97 | AM7: 0.952 | AN7: 0.97 | AO7: 0.969 | AP7: 0.98 | AQ7: 0.965 | AR7: 0.95 | AS7: 0.98 | AT7: 0.97 | AU7: 0.99 | AV7: 0.99 | AW7: 0.99 | AX7: 0.97 | AY7: 1 | AZ7: 0.97 | BA7: 0.98 | BB7: 0.99 | BC7: 1 | BD7: 0.99 | BE7: 0.99 | BF7: 1 | BG7: 1 | BH7: 0.98 | BI7: 0.99 | BJ7: 0.99 | BK7: 0.94 | BL7: 0.85 | BM7: 0.17 | BN7: 0.97 | BO7: 1 | BP7: 1 | BQ7: 0.94 | BR7: 1 | BS7: 1 | BT7: 0.98 | BU7: 1 | BV7: 0.95 | BW7: 0.91 | BX7: 0.98 | BY7: 1 | BZ7: 1 | CA7: 1 | CB7: 0.94 | CC7: 1 | CD7: 1 | CE7: 1 | CF7: 1 | CG7: 1 | CH7: 1 | CI7: 1 | CJ7: 0.99 | CK7: 0.99 | CL7: 0.93 | CM7: 0.94 | CN7: 0.857 | CO7: 1 | CP7: 0.928 | CQ7: 1 | CR7: 0.971 | CS7: 1 | CT7: 0.973 | CU7: 1 | CV7: 0.984 | CW7: 1 | CX7: 0.98 | CY7: 1 | CZ7: 0.77 | DA7: 1 | DB7: 1 | DC7: 0.88 | DD7: 0.94 | DE7: 1 | DF7: 0.99 | DG7: 1 | DH7: 0.95 | DI7: 0.99 | DJ7: 0.98 | DK7: 1 | DL7: 0.96 | DM7: 0.93 | DN7: 0.89 | DO7: 1 | DP7: 0.81 | DQ7: 1 | DR7: 0.63 | DS7: 0.98 | DT7: 0.82 | DU7: 0.64 | DV7: 0.94 | DW7: 0.99 | DX7: 0.93 | DY7: 1 | DZ7: 0.97 | EA7: 1 | EB7: 0.97 | EC7: 0.89 | ED7: 0.83 | EE7: 1 | EF7: 0.95 | EG7: 0.96 | EH7: 0.96 | EI7: 1 | EJ7: 0.96 | EK7: 0.98 | EL7: 0.96 | EM7: 0.98 | EN7: 0.9 | EO7: 0.98 | EP7: 0.95 | EQ7: 1
A8: Taux des perdus | AF8: 0.03 | AG8: 0 | AH8: 0.04 | AI8: 0.065 | AJ8: 0.13 | AK8: 0 | AL8: 0.03 | AM8: 0.048 | AN8: 0.03 | AO8: 0.031 | AP8: 0.02 | AQ8: 0.035 | AR8: 0.05 | AS8: 0.023 | AT8: 0.03 | AU8: 0.01 | AV8: 0.01 | AW8: 0.013 | AX8: 0.03 | AY8: 0 | AZ8: 0.03 | BA8: 0.022 | BB8: 0.01 | BC8: 0 | BD8: 0.01 | BE8: 0.013 | BF8: 0 | BG8: 0 | BH8: 0.02 | BI8: 0.01 | BJ8: 0.01 | BK8: 0.06 | BL8: 0.15 | BM8: 0.833 | BN8: 0.03 | BO8: 0 | BP8: 0 | BQ8: 0.063 | BR8: 0 | BS8: 0 | BT8: 0.02 | BU8: 0 | BV8: 0.05 | BW8: 0.091 | BX8: 0.02 | BY8: 0 | BZ8: 0 | CA8: 0 | CB8: 0.06 | CC8: 0 | CD8: 0 | CE8: 0 | CF8: 0 | CG8: 0 | CH8: 0 | CI8: 0 | CJ8: 0.01 | CK8: 0.011 | CL8: 0.07 | CM8: 0.057 | CN8: 0.143 | CO8: 0 | CP8: 0.072 | CQ8: 0 | CR8: 0.029 | CS8: 0 | CT8: 0.027 | CU8: 0 | CV8: 0.016 | CW8: 0 | CX8: 0.02 | CY8: 0 | CZ8: 0.23 | DA8: 0 | DB8: 0 | DC8: 0.13 | DD8: 0.06 | DE8: 0 | DF8: 0.01 | DG8: 0 | DH8: 0.05 | DI8: 0.01 | DJ8: 0.02 | DK8: 0 | DL8: 0.05 | DM8: 0.07 | DN8: 0.11 | DO8: 0 | DP8: 0.19 | DQ8: 0 | DR8: 0.37 | DS8: 0.02 | DT8: 0.18 | DU8: 0.36 | DV8: 0.07 | DW8: 0.01 | DX8: 0.07 | DY8: 0 | DZ8: 0.03 | EA8: 0 | EB8: 0.03 | EC8: 0.11 | ED8: 0.17 | EE8: 0 | EF8: 0.05 | EG8: 0.04 | EH8: 0.05 | EI8: 0 | EJ8: 0.04 | EK8: 0.02 | EL8: 0.04 | EM8: 0.02 | EN8: 0.1 | EO8: 0.02 | EP8: 0.05 | EQ8: 0
A9: Taux des abandonnés | AF9: 0 | AG9: 0.014 | AH9: 0.022 | AI9: 0.037 | AJ9: 0 | AK9: 0 | AL9: 0.01 | AM9: 0 | AN9: 0.019 | AO9: 0 | AP9: 0.02 | AQ9: 0.047 | AR9: 0.01 | AS9: 0 | AT9: 0.009 | AU9: 0.021 | AV9: 0.027 | AW9: 0.013 | AX9: 0 | AY9: 0 | AZ9: 0 | BA9: 0 | BB9: 0.024 | BC9: 0.011 | BD9: 0 | BE9: 0 | BF9: 0 | BG9: 0.012 | BH9: 0 | BI9: 0 | BJ9: 0.009 | BK9: 0 | BL9: 0 | BM9: 0 | BN9: 0.007 | BO9: 0 | BP9: 0.008 | BQ9: 0 | BR9: 0 | BS9: 0.053 | BT9: 0 | BU9: 0.015 | BV9: 0.02 | BW9: 0 | BX9: 0.016 | BY9: 0.026 | BZ9: 0 | CA9: 0 | CB9: 0.008 | CC9: 0 | CD9: 0 | CE9: 0.013 | CF9: 0 | CG9: 0.043 | CH9: 0 | CI9: 0 | CJ9: 0.014 | CK9: 0.022 | CL9: 0 | CM9: 0.014 | CN9: 0 | CO9: 0 | CP9: 0.021 | CQ9: 0 | CR9: 0 | CS9: 0.012 | CT9: 0.014 | CU9: 0.015 | CV9: 0.025 | CW9: 0 | CX9: 0.02 | CY9: 0 | CZ9: 0.213 | DA9: 0 | DB9: 0 | DC9: 0 | DD9: 0.01 | DE9: 0 | DF9: 0.01 | DG9: 0.034 | DH9: 0.062 | DI9: 0 | DJ9: 0.009 | DK9: 0.037 | DL9: 0.052 | DM9: 0.019 | DN9: 0.05 | DO9: 0 | DP9: 0 | DQ9: 0 | DR9: 0.052 | DS9: 0.019 | DT9: 0.012 | DU9: 0.064 | DV9: 0.007 | DW9: 0 | DX9: 0.008 | DY9: 0 | DZ9: 0.033 | EA9: 0.02 | EB9: 0.009 | EC9: 0.03 | ED9: 0.042 | EE9: 0 | EF9: 0 | EG9: 0.015 | EH9: 0.018 | EI9: 0 | EJ9: 0.009 | EK9: 0.022 | EL9: 0.029 | EM9: 0.054 | EN9: 0.029 | EO9: 0.019 | EP9: 0.012 | EQ9: 0
CN10: ='Daily-DS.M-QS'!CN3+'Daily-DS.M-QS'!CP3+'Daily-DS.M-QS'!CR3+'Daily-DS.M-QS'!CT3+'Daily-DS.M-QS'!CV3+'Daily-DS.M-QS'!CX3+'Daily-DS.M-QS'!CZ3 -> 762
A11: Durée Moy. d'attente | AF11: 0.038194444 | AG11: 0.01875 | AH11: 0.041666667 | AI11: 0.032638889 | AJ11: 0.0090277778 | AK11: 0.0069444444 | AL11: 0.020138889 | AM11: 0.045138889 | AN11: 0.03125 | AO11: 0.025 | AP11: 0.033333333 | AQ11: 0.026388889 | AR11: 0.020138889 | AS11: 0.03125 | AT11: 0.020138889 | AU11: 0.03125 | AV11: 0.013888889 | AW11: 0.015972222 | AX11: 0.021527778 | AY11: 0.011805556 | AZ11: 0.020138889 | BA11: 0.011805556 | BB11: 0.011805556 | BC11: 0.0125 | BD11: 0.0090277778 | BE11: 0.020138889 | BF11: 0.017361111 | BG11: 0.011805556 | BH11: 0.022916667 | BI11: 0.019444444 | BJ11: 0.013888889 | BK11: 0.022222222 | BL11: 0.0375 | BM11: 0.0013888889 | BN11: 0.042361111 | BO11: 0.016666667 | BP11: 0.011111111 | BQ11: 0.025694444 | BR11: 0.011111111 | BS11: 0.0125 | BT11: 0.0097222222 | BU11: 0.016666667 | BV11: 0.025694444 | BW11: 0.044444444 | BX11: 0.020833333 | BY11: 0.0125 | BZ11: 0.0069444444 | CA11: 0.0097222222 | CB11: 0.054861111 | CC11: 0.019444444 | CD11: 0.013194444 | CE11: 0.0097222222 | CF11: 0.019444444 | CG11: 0.013194444 | CH11: 0.015972222 | CI11: 0.011111111 | CJ11: 0.011805556 | CK11: 0.022916667 | CL11: 0.036805556 | CM11: 0.015972222 | CN11: 0.020833333 | CO11: 0.0069444444 | CP11: 0.05 | CQ11: 0.011805556 | CR11: 0.014583333 | CS11: 0.020138889 | CT11: 0.022916667 | CU11: 0.010416667 | CV11: 0.015972222 | CW11: 0.0125 | CX11: 0.015972222 | CY11: 0.011111111 | CZ11: 0.016666667 | DA11: 0.013194444 | DB11: 0.038888889 | DC11: 0.011111111 | DD11: 0.052777778 | DE11: 0.011805556 | DF11: 0.020833333 | DG11: 0.011805556 | DH11: 0.028472222 | DI11: 0.020833333 | DJ11: 0.014583333 | DK11: 0.031944444 | DL11: 0.034027778 | DM11: 0.038888889 | DN11: 0.049305556 | DO11: 0.011805556 | DP11: 0.092361111 | DQ11: 0.0069444444 | DR11: 0.11597222 | DS11: 0.014583333 | DT11: 0.10277778 | DU11: 0.01875 | DV11: 0.034027778 | DW11: 0.0125 | DX11: 0.052083333 | DY11: 0.014583333 | DZ11: 0.020138889 | EA11: 0.015972222 | EB11: 0.034027778 | EC11: 0.013194444 | ED11: 0.017361111 | EE11: 0.011111111 | EF11: 0.042361111 | EG11: 0.025 | EH11: 0.027777778 | EI11: 0.021527778 | EJ11: 0.038888889 | EK11: 0.028472222 | EL11: 0.040972222 | EM11: 0.016666667 | EN11: 0.050694444 | EO11: 0.01875 | EP11: 0.033333333 | EQ11: 0.011805556
A12: Durée Moy. de communication | AF12: 0.22916667 | AG12: 0.30277778 | AH12: 0.22916667 | AI12: 0.19027778 | AJ12: 0.27847222 | AK12: 0.10069444 | AL12: 0.29166667 | AM12: 0.18541667 | AN12: 0.3125 | AO12: 0.22847222 | AP12: 0.22361111 | AQ12: 0.19097222 | AR12: 0.25 | AS12: 0.17430556 | AT12: 0.33958333 | AU12: 0.19513889 | AV12: 0.26597222 | AW12: 0.17222222 | AX12: 0.39722222 | AY12: 0.15277778 | AZ12: 0.40763889 | BA12: 0.21458333 | BB12: 0.25416667 | BC12: 0.2125 | BD12: 0.23888889 | BE12: 0.175 | BF12: 0.25625 | BG12: 0.30277778 | BH12: 0.27708333 | BI12: 0.19583333 | BJ12: 0.30277778 | BK12: 0.15833333 | BL12: 0.19652778 | BM12: 0.0125 | BN12: 0.27152778 | BO12: 0.27777778 | BP12: 0.24097222 | BQ12: 0.21944444 | BR12: 0.26041667 | BS12: 0.21111111 | BT12: 0.26180556 | BU12: 0.14444444 | BV12: 0.29305556 | BW12: 0.18819444 | BX12: 0.32777778 | BY12: 0.19236111 | BZ12: 0.19722222 | CA12: 0.43194444 | CB12: 0.3875 | CC12: 0.24027778 | CD12: 0.26805556 | CE12: 0.19097222 | CF12: 0.3875 | CG12: 0.15972222 | CH12: 0.25763889 | CI12: 0.18402778 | CJ12: 0.225 | CK12: 0.20833333 | CL12: 0.27916667 | CM12: 0.22222222 | CN12: 0.31111111 | CO12: 0.45347222 | CP12: 0.33958333 | CQ12: 0.22986111 | CR12: 0.32916667 | CS12: 0.22986111 | CT12: 0.32708333 | CU12: 0.26736111 | CV12: 0.22986111 | CW12: 0.24236111 | CX12: 0.34861111 | CY12: 0.18611111 | CZ12: 0.15902778 | DA12: 0.26458333 | DB12: 0.24861111 | DC12: 0.18680556 | DD12: 0.32291667 | DE12: 0.23055556 | DF12: 0.4 | DG12: 0.23055556 | DH12: 0.32083333 | DI12: 0.21041667 | DJ12: 0.32013889 | DK12: 0.22708333 | DL12: 0.31388889 | DM12: 0.18958333 | DN12: 0.32777778 | DO12: 0.22430556 | DP12: 0.38819444 | DQ12: 0.40555556 | DR12: 0.21666667 | DS12: 0.20833333 | DT12: 0.29791667 | DU12: 0.12013889 | DV12: 0.33194444 | DW12: 0.21319444 | DX12: 0.37222222 | DY12: 0.19166667 | DZ12: 0.24930556 | EA12: 0.21458333 | EB12: 0.26319444 | EC12: 0.20347222 | ED12: 0.43472222 | EE12: 0.090972222 | EF12: 0.41736111 | EG12: 0.17430556 | EH12: 0.31805556 | EI12: 0.20972222 | EJ12: 0.2375 | EK12: 0.19930556 | EL12: 0.30902778 | EM12: 0.22708333 | EN12: 0.24861111 | EO12: 0.17916667 | EP12: 0.28680556 | EQ12: 0.22708333
A14: Appels courts < 15s | AF14: 12 | AG14: 7 | AH14: 9 | AI14: 11 | AJ14: 1 | AK14: 1 | AL14: 4 | AM14: 3 | AN14: 9 | AO14: 6 | AP14: 5 | AQ14: 5 | AR14: 0 | AS14: 4 | AT14: 10 | AU14: 3 | AV14: 13 | AW14: 4 | AX14: 0 | AY14: 0 | AZ14: 5 | BA14: 3 | BB14: 3 | BC14: 6 | BD14: 6 | BE14: 8 | BF14: 6 | BG14: 6 | BH14: 7 | BI14: 8 | BJ14: 7 | BK14: 15 | BL14: 4 | BM14: 0 | BN14: 5 | BO14: 5 | BP14: 7 | BQ14: 5 | BR14: 11 | BS14: 11 | BT14: 10 | BU14: 9 | BV14: 8 | BW14: 3 | BX14: 14 | BY14: 5 | BZ14: 3 | CA14: 0 | CB14: 11 | CC14: 1 | CD14: 10 | CE14: 4 | CF14: 2 | CG14: 4 | CH14: 4 | CI14: 4 | CJ14: 7 | CK14: 7 | CL14: 14 | CM14: 1 | CN14: 1 | CO14: 0 | CP14: 1 | CQ14: 2 | CR14: 4 | CS14: 3 | CT14: 5 | CU14: 3 | CV14: 7 | CW14: 7 | CX14: 2 | CY14: 3 | CZ14: 27 | DA14: 2 | DB14: 2 | DC14: 0 | DD14: 6 | DE14: 2 | DF14: 1 | DG14: 4 | DH14: 7 | DI14: 4 | DJ14: 5 | DK14: 7 | DL14: 7 | DM14: 6 | DN14: 4 | DO14: 10 | DP14: 0 | DQ14: 0 | DR14: 4 | DS14: 3 | DT14: 8 | DU14: 6 | DV14: 4 | DW14: 8 | DX14: 3 | DY14: 6 | DZ14: 1 | EA14: 5 | EB14: 4 | EC14: 1 | ED14: 2 | EE14: 1 | EF14: 2 | EG14: 3 | EH14: 5 | EI14: 5 | EJ14: 4 | EK14: 10 | EL14: 11 | EM14: 1 | EN14: 1 | EO14: 6 | EP14: 1 | EQ14: 2
A15: Taux de conformité | AF15: 0.1053 | AG15: 0.0986 | AH15: 0.0677 | AI15: 0.1089 | AJ15: 0.0357 | AK15: 0.3333 | AL15: 0.0412 | AM15: 0.075 | AN15: 0.0857 | AO15: 0.0952 | AP15: 0.0505 | AQ15: 0.061 | AR15: 0 | AS15: 0.0476 | AT15: 0.0901 | AU15: 0.0313 | AV15: 0.1193 | AW15: 0.0513 | AX15: 0 | AY15: 0 | AZ15: 0.0568 | BA15: 0.0682 | BB15: 0.037 | BC15: 0.069 | BD15: 0.0588 | BE15: 0.1053 | BF15: 0.0588 | BG15: 0.0723 | BH15: 0.0593 | BI15: 0.0769 | BJ15: 0.0609 | BK15: 0.0877 | BL15: 0.1143 | BM15: 0 | BN15: 0.0379 | BO15: 0.0943 | BP15: 0.0526 | BQ15: 0.0676 | BR15: 0.1111 | BS15: 0.1467 | BT15: 0.0855 | BU15: 0.1364 | BV15: 0.0563 | BW15: 0.06 | BX15: 0.1167 | BY15: 0.0658 | BZ15: 0.1034 | CA15: 0 | CB15: 0.0982 | CC15: 0.0263 | CD15: 0.0893 | CE15: 0.0519 | CF15: 0.0244 | CG15: 0.0426 | CH15: 0.0396 | CI15: 0.0494 | CJ15: 0.0972 | CK15: 0.0769 | CL15: 0.1414 | CM15: 0.0152 | CN15: 0.0833 | CO15: 0 | CP15: 0.0111 | CQ15: 0.05 | CR15: 0.0396 | CS15: 0.0366 | CT15: 0.0352 | CU15: 0.0448 | CV15: 0.0583 | CW15: 0.0875 | CX15: 0.0417 | CY15: 0.1364 | CZ15: 0.1525 | DA15: 0.0339 | DB15: 0.1053 | DC15: 0 | DD15: 0.0645 | DE15: 0.0833 | DF15: 0.0102 | DG15: 0.0678 | DH15: 5,65% | DI15: 5,00% | DJ15: 4,39% | DK15: 8,54% | DL15: 4,73% | DM15: 6,06% | DN15: 3,23% | DO15: 7,35% | DP15: 0,00% | DQ15: 0,00% | DR15: 4,71% | DS15: 5,77% | DT15: 5,93% | DU15: 5,45% | DV15: 2,80% | DW15: 8,08% | DX15: 2,42% | DY15: 3,64% | DZ15: 1,14% | EA15: 5,95% | EB15: 3,57% | EC15: 1,69% | ED15: 10,00% | EE15: 11,11% | EF15: 2,86% | EG15: 4,62% | EH15: 4,76% | EI15: 8,06% | EJ15: 3,60% | EK15: 11,24% | EL15: 8,30% | EM15: 8,30% | EN15: 1,60% | EO15: 1,60% | EP15: 1,30% | EQ15: 1,30%
