Workbook

Sheet Synthèse
B1: Daily | I1: Weekly | P1: Monthly
B2: 46035 | D2: Trame de résolution | F2: Type de résolution | I2: S19 | K2: Trame de résolution | M2: Type de résolution | P2: 5 | R2: Trame de résolution | T2: Type de résolution
B3: Bannettes | C3: Nr ticket | D3: OK | E3: KO | F3: OK | G3: KO | I3: Bannettes | J3: Nr ticket | K3: OK | L3: KO | M3: OK | N3: KO | P3: Bannettes | Q3: Nr ticket | R3: OK | S3: KO | T3: OK | U3: KO
B4: FO | C4: =COUNTIFS(Picking!A:A,$B$2,Picking!E:E,B4) -> 0 | D4: =IFERROR((COUNTIFS(Picking!A:A,$B$2,Picking!E:E,B4,Picking!O:O,1)/C4),"") | E4: =IFERROR((COUNTIFS(Picking!A:A,$B$2,Picking!E:E,B4,Picking!O:O,0)/C4),"") | F4: =IFERROR((COUNTIFS(Picking!A:A,$B$2,Picking!E:E,B4,Picking!P:P,1)/C4),"") | G4: =IFERROR((COUNTIFS(Picking!A:A,$B$2,Picking!E:E,B4,Picking!P:P,0)/C4),"") | I4: FO | J4: =COUNTIFS(Picking!B:B,$I$2,Picking!E:E,I4) -> 0 | K4: =IFERROR((COUNTIFS(Picking!B:B,$I$2,Picking!E:E,I4,Picking!O:O,1)/J4),"") | L4: =IFERROR((COUNTIFS(Picking!B:B,$I$2,Picking!E:E,I4,Picking!O:O,0)/J4),"") | M4: =IFERROR((COUNTIFS(Picking!B:B,$I$2,Picking!E:E,I4,Picking!P:P,1)/J4),"") | N4: =IFERROR((COUNTIFS(Picking!B:B,$I$2,Picking!E:E,I4,Picking!P:P,0)/J4),"") | P4: FO | Q4: =COUNTIFS(Picking!C:C,$P$2,Picking!E:E,P4) -> 0 | R4: =IFERROR((COUNTIFS(Picking!C:C,$P$2,Picking!E:E,P4,Picking!O:O,1)/Q4),"") | S4: =IFERROR((COUNTIFS(Picking!C:C,$P$2,Picking!E:E,P4,Picking!O:O,0)/Q4),"") | T4: =IFERROR((COUNTIFS(Picking!C:C,$P$2,Picking!E:E,P4,Picking!P:P,1)/Q4),"") | U4: =IFERROR((COUNTIFS(Picking!C:C,$P$2,Picking!E:E,P4,Picking!P:P,0)/Q4),"")
B5: BO | C5: =COUNTIFS(Picking!A:A,$B$2,Picking!E:E,B5) -> 0 | D5: =IFERROR((COUNTIFS(Picking!A:A,$B$2,Picking!E:E,B5,Picking!O:O,1)/C5),"") | E5: =IFERROR((COUNTIFS(Picking!A:A,$B$2,Picking!E:E,B5,Picking!O:O,0)/C5),"") | F5: =IFERROR((COUNTIFS(Picking!A:A,$B$2,Picking!E:E,B5,Picking!P:P,1)/C5),"") | G5: =IFERROR((COUNTIFS(Picking!A:A,$B$2,Picking!E:E,B5,Picking!P:P,0)/C5),"") | I5: BO | J5: =COUNTIFS(Picking!B:B,$I$2,Picking!E:E,I5) -> 0 | K5: =IFERROR((COUNTIFS(Picking!B:B,$I$2,Picking!E:E,I5,Picking!O:O,1)/J5),"") | L5: =IFERROR((COUNTIFS(Picking!B:B,$I$2,Picking!E:E,I5,Picking!O:O,0)/J5),"") | M5: =IFERROR((COUNTIFS(Picking!B:B,$I$2,Picking!E:E,I5,Picking!P:P,1)/J5),"") | N5: =IFERROR((COUNTIFS(Picking!B:B,$I$2,Picking!E:E,I5,Picking!P:P,0)/J5),"") | P5: BO | Q5: =COUNTIFS(Picking!C:C,$P$2,Picking!E:E,P5) -> 0 | R5: =IFERROR((COUNTIFS(Picking!C:C,$P$2,Picking!E:E,P5,Picking!O:O,1)/Q5),"") | S5: =IFERROR((COUNTIFS(Picking!C:C,$P$2,Picking!E:E,P5,Picking!O:O,0)/Q5),"") | T5: =IFERROR((COUNTIFS(Picking!C:C,$P$2,Picking!E:E,P5,Picking!P:P,1)/Q5),"") | U5: =IFERROR((COUNTIFS(Picking!C:C,$P$2,Picking!E:E,P5,Picking!P:P,0)/Q5),"")
B6: PROXI-PMC | C6: =COUNTIFS(Picking!A:A,$B$2,Picking!E:E,B6) -> 0 | D6: =IFERROR((COUNTIFS(Picking!A:A,$B$2,Picking!E:E,B6,Picking!O:O,1)/C6),"") | E6: =IFERROR((COUNTIFS(Picking!A:A,$B$2,Picking!E:E,B6,Picking!O:O,0)/C6),"") | F6: =IFERROR((COUNTIFS(Picking!A:A,$B$2,Picking!E:E,B6,Picking!P:P,1)/C6),"") | G6: =IFERROR((COUNTIFS(Picking!A:A,$B$2,Picking!E:E,B6,Picking!P:P,0)/C6),"") | I6: PROXI-PMC | J6: =COUNTIFS(Picking!B:B,$I$2,Picking!E:E,I6) -> 0 | K6: =IFERROR((COUNTIFS(Picking!B:B,$I$2,Picking!E:E,I6,Picking!O:O,1)/J6),"") | L6: =IFERROR((COUNTIFS(Picking!B:B,$I$2,Picking!E:E,I6,Picking!O:O,0)/J6),"") | M6: =IFERROR((COUNTIFS(Picking!B:B,$I$2,Picking!E:E,I6,Picking!P:P,1)/J6),"") | N6: =IFERROR((COUNTIFS(Picking!B:B,$I$2,Picking!E:E,I6,Picking!P:P,0)/J6),"") | P6: PROXI-PMC | Q6: =COUNTIFS(Picking!C:C,$P$2,Picking!E:E,P6) -> 0 | R6: =IFERROR((COUNTIFS(Picking!C:C,$P$2,Picking!E:E,P6,Picking!O:O,1)/Q6),"") | S6: =IFERROR((COUNTIFS(Picking!C:C,$P$2,Picking!E:E,P6,Picking!O:O,0)/Q6),"") | T6: =IFERROR((COUNTIFS(Picking!C:C,$P$2,Picking!E:E,P6,Picking!P:P,1)/Q6),"") | U6: =IFERROR((COUNTIFS(Picking!C:C,$P$2,Picking!E:E,P6,Picking!P:P,0)/Q6),"")
B7: Partenaire | C7: =COUNTIFS(Picking!A:A,$B$2,Picking!E:E,B7) -> 0 | D7: =IFERROR((COUNTIFS(Picking!A:A,$B$2,Picking!E:E,B7,Picking!O:O,1)/C7),"") | E7: =IFERROR((COUNTIFS(Picking!A:A,$B$2,Picking!E:E,B7,Picking!O:O,0)/C7),"") | F7: =IFERROR((COUNTIFS(Picking!A:A,$B$2,Picking!E:E,B7,Picking!P:P,1)/C7),"") | G7: =IFERROR((COUNTIFS(Picking!A:A,$B$2,Picking!E:E,B7,Picking!P:P,0)/C7),"") | I7: Partenaire | J7: =COUNTIFS(Picking!B:B,$I$2,Picking!E:E,I7) -> 0 | K7: =IFERROR((COUNTIFS(Picking!B:B,$I$2,Picking!E:E,I7,Picking!O:O,1)/J7),"") | L7: =IFERROR((COUNTIFS(Picking!B:B,$I$2,Picking!E:E,I7,Picking!O:O,0)/J7),"") | M7: =IFERROR((COUNTIFS(Picking!B:B,$I$2,Picking!E:E,I7,Picking!P:P,1)/J7),"") | N7: =IFERROR((COUNTIFS(Picking!B:B,$I$2,Picking!E:E,I7,Picking!P:P,0)/J7),"") | P7: Partenaire | Q7: =COUNTIFS(Picking!C:C,$P$2,Picking!E:E,P7) -> 0 | R7: =IFERROR((COUNTIFS(Picking!C:C,$P$2,Picking!E:E,P7,Picking!O:O,1)/Q7),"") | S7: =IFERROR((COUNTIFS(Picking!C:C,$P$2,Picking!E:E,P7,Picking!O:O,0)/Q7),"") | T7: =IFERROR((COUNTIFS(Picking!C:C,$P$2,Picking!E:E,P7,Picking!P:P,1)/Q7),"") | U7: =IFERROR((COUNTIFS(Picking!C:C,$P$2,Picking!E:E,P7,Picking!P:P,0)/Q7),"")
B8: Supply | C8: =COUNTIFS(Picking!A:A,$B$2,Picking!E:E,B8) -> 0 | D8: =IFERROR((COUNTIFS(Picking!A:A,$B$2,Picking!E:E,B8,Picking!O:O,1)/C8),"") | E8: =IFERROR((COUNTIFS(Picking!A:A,$B$2,Picking!E:E,B8,Picking!O:O,0)/C8),"") | F8: =IFERROR((COUNTIFS(Picking!A:A,$B$2,Picking!E:E,B8,Picking!P:P,1)/C8),"") | G8: =IFERROR((COUNTIFS(Picking!A:A,$B$2,Picking!E:E,B8,Picking!P:P,0)/C8),"") | I8: Supply | J8: =COUNTIFS(Picking!B:B,$I$2,Picking!E:E,I8) -> 0 | K8: =IFERROR((COUNTIFS(Picking!B:B,$I$2,Picking!E:E,I8,Picking!O:O,1)/J8),"") | L8: =IFERROR((COUNTIFS(Picking!B:B,$I$2,Picking!E:E,I8,Picking!O:O,0)/J8),"") | M8: =IFERROR((COUNTIFS(Picking!B:B,$I$2,Picking!E:E,I8,Picking!P:P,1)/J8),"") | N8: =IFERROR((COUNTIFS(Picking!B:B,$I$2,Picking!E:E,I8,Picking!P:P,0)/J8),"") | P8: Supply | Q8: =COUNTIFS(Picking!C:C,$P$2,Picking!E:E,P8) -> 0 | R8: =IFERROR((COUNTIFS(Picking!C:C,$P$2,Picking!E:E,P8,Picking!O:O,1)/Q8),"") | S8: =IFERROR((COUNTIFS(Picking!C:C,$P$2,Picking!E:E,P8,Picking!O:O,0)/Q8),"") | T8: =IFERROR((COUNTIFS(Picking!C:C,$P$2,Picking!E:E,P8,Picking!P:P,1)/Q8),"") | U8: =IFERROR((COUNTIFS(Picking!C:C,$P$2,Picking!E:E,P8,Picking!P:P,0)/Q8),"")
B9: DS-Magasin | C9: =SUM(C4:C8) -> 0 | D9: =IFERROR((COUNTIFS(Picking!A:A,$B$2,Picking!O:O,1)/C9),"") | E9: =IFERROR((COUNTIFS(Picking!A:A,$B$2,Picking!O:O,0)/C9),"") | F9: =IFERROR((COUNTIFS(Picking!A:A,$B$2,Picking!P:P,1)/C9),"") | G9: =IFERROR((COUNTIFS(Picking!A:A,$B$2,Picking!P:P,0)/C9),"") | I9: DS-Magasin | J9: =SUM(J4:J8) -> 0 | K9: =IFERROR((COUNTIFS(Picking!B:B,$I$2,Picking!O:O,1)/J9),"") | L9: =IFERROR((COUNTIFS(Picking!B:B,$I$2,Picking!O:O,0)/J9),"") | M9: =IFERROR((COUNTIFS(Picking!B:B,$I$2,Picking!P:P,1)/J9),"") | N9: =IFERROR((COUNTIFS(Picking!B:B,$I$2,Picking!P:P,0)/J9),"") | P9: DS-Magasin | Q9: =SUM(Q4:Q8) -> 0 | R9: =IFERROR((COUNTIFS(Picking!C:C,$P$2,Picking!O:O,1)/Q9),"") | S9: =IFERROR((COUNTIFS(Picking!C:C,$P$2,Picking!O:O,0)/Q9),"") | T9: =IFERROR((COUNTIFS(Picking!C:C,$P$2,Picking!P:P,1)/Q9),"") | U9: =IFERROR((COUNTIFS(Picking!C:C,$P$2,Picking!P:P,0)/Q9),"")

Sheet Picking
A1: ID Ticket | B1: Titre | C1: Description | D1: Solution | E1: Type de résolution | F1: Synthèse de la demande | G1: Actions / Résultat | H1: Formule de politesse | I1: Conformité Solution | J1: Conformité Type de Résolution | K1: Correction Type de résolution | L1: Actions Sup | M1: Commentaire Sup
A2: 101906873 | F2: 1 | G2: 1 | H2: 1 | I2: =IF(COUNTA(F2:H2)<3,"",IF(AND(F2=1,G2=1,H2=1),1,0)) -> 1 | J2: 1 | K2: Conforme
A3: 101960296 | F3: 1 | G3: 1 | H3: 1 | I3: =IF(COUNTA(F3:H3)<3,"",IF(AND(F3=1,G3=1,H3=1),1,0)) -> 1 | J3: 1 | K3: Conforme
A4: 102028083 | F4: 1 | G4: 0 | H4: 1 | I4: =IF(COUNTA(F4:H4)<3,"",IF(AND(F4=1,G4=1,H4=1),1,0)) -> 0 | J4: 1 | K4: Conforme
A5: 101936765 | F5: 1 | G5: 1 | H5: 1 | I5: =IF(COUNTA(F5:H5)<3,"",IF(AND(F5=1,G5=1,H5=1),1,0)) -> 1 | J5: 1 | K5: Conforme
A6: 101938802 | F6: 1 | G6: 1 | H6: 1 | I6: =IF(COUNTA(F6:H6)<3,"",IF(AND(F6=1,G6=1,H6=1),1,0)) -> 1 | J6: 0 | K6: 01 - Aide à l’utilisation
A7: 101362015 | F7: 1 | G7: 1 | H7: 1 | I7: =IF(COUNTA(F7:H7)<3,"",IF(AND(F7=1,G7=1,H7=1),1,0)) -> 1 | J7: 1 | K7: Conforme
A8: 101860991 | F8: 1 | G8: 1 | H8: 1 | I8: =IF(COUNTA(F8:H8)<3,"",IF(AND(F8=1,G8=1,H8=1),1,0)) -> 1 | J8: 1 | K8: 04 - Aucune action nécessaire ou possible
A9: 101923390 | F9: 1 | G9: 1 | H9: 1 | I9: =IF(COUNTA(F9:H9)<3,"",IF(AND(F9=1,G9=1,H9=1),1,0)) -> 1 | J9: 1 | K9: Conforme
A10: 102011417 | F10: 1 | G10: 1 | H10: 1 | I10: =IF(COUNTA(F10:H10)<3,"",IF(AND(F10=1,G10=1,H10=1),1,0)) -> 1 | J10: 0 | K10: 03 - Script, fix ou contournement
A11: 101972013 | F11: 1 | G11: 1 | H11: 1 | I11: =IF(COUNTA(F11:H11)<3,"",IF(AND(F11=1,G11=1,H11=1),1,0)) -> 1 | J11: 1 | K11: Conforme
A12: 101961756 | F12: 1 | G12: 1 | H12: 1 | I12: =IF(COUNTA(F12:H12)<3,"",IF(AND(F12=1,G12=1,H12=1),1,0)) -> 1 | J12: 0 | K12: 01 - Aide à l’utilisation
A13: 101820880 | F13: 1 | G13: 1 | H13: 1 | I13: =IF(COUNTA(F13:H13)<3,"",IF(AND(F13=1,G13=1,H13=1),1,0)) -> 1 | J13: 1 | K13: Conforme
... A28: 101902986 | F28: 1 | G28: 1 | H28: 1 | I28: =IF(COUNTA(F28:H28)<3,"",IF(AND(F28=1,G28=1,H28=1),1,0)) -> 1 | J28: 1 | K28: Conforme
A29: 101436098 | F29: 1 | G29: 1 | H29: 1 | I29: =IF(COUNTA(F29:H29)<3,"",IF(AND(F29=1,G29=1,H29=1),1,0)) -> 1 | J29: 0 | K29: 05 - Hors périmètre support | M29: L'attribution des droits d'accès sont hors périmètre support.
A30: 101960078 | F30: 1 | G30: 1 | H30: 1 | I30: =IF(COUNTA(F30:H30)<3,"",IF(AND(F30=1,G30=1,H30=1),1,0)) -> 1 | J30: 0 | K30: 01 - Aide à l’utilisation
A31: 102027025 | F31: 1 | G31: 1 | H31: 1 | I31: =IF(COUNTA(F31:H31)<3,"",IF(AND(F31=1,G31=1,H31=1),1,0)) -> 1 | J31: 0 | K31: 03 - Script, fix ou contournement
A32: 101904715 | F32: 1 | G32: 1 | H32: 1 | I32: =IF(COUNTA(F32:H32)<3,"",IF(AND(F32=1,G32=1,H32=1),1,0)) -> 1 | J32: 1 | K32: Conforme
A33: 102010905 | F33: 1 | G33: 1 | H33: 1 | I33: =IF(COUNTA(F33:H33)<3,"",IF(AND(F33=1,G33=1,H33=1),1,0)) -> 1 | J33: 1 | K33: Conforme
A34: 101977407 | F34: 1 | G34: 1 | H34: 1 | I34: =IF(COUNTA(F34:H34)<3,"",IF(AND(F34=1,G34=1,H34=1),1,0)) -> 1 | J34: 0 | K34: 03 - Script, fix ou contournement
A35: 101997967 | F35: 1 | G35: 1 | H35: 1 | I35: =IF(COUNTA(F35:H35)<3,"",IF(AND(F35=1,G35=1,H35=1),1,0)) -> 1 | J35: 0 | K35: 01 - Aide à l’utilisation
A36: 102037863 | F36: 1 | G36: 0 | H36: 1 | I36: =IF(COUNTA(F36:H36)<3,"",IF(AND(F36=1,G36=1,H36=1),1,0)) -> 0 | J36: 1 | K36: Conforme | M36: Action non mentionnée.
A37: 101661869 | F37: 1 | G37: 1 | H37: 1 | I37: =IF(COUNTA(F37:H37)<3,"",IF(AND(F37=1,G37=1,H37=1),1,0)) -> 1 | J37: 1 | K37: Conforme
A38: 101893115 | F38: 1 | G38: 1 | H38: 1 | I38: =IF(COUNTA(F38:H38)<3,"",IF(AND(F38=1,G38=1,H38=1),1,0)) -> 1 | J38: 0 | K38: 02 - Correction donnée ou modification de paramétrage
A39: 101893164 | F39: 1 | G39: 1 | H39: 1 | I39: =IF(COUNTA(F39:H39)<3,"",IF(AND(F39=1,G39=1,H39=1),1,0)) -> 1 | J39: 1 | K39: 01 - Aide à l’utilisation
A40: 101920245 | F40: 1 | G40: 1 | H40: 1 | I40: =IF(COUNTA(F40:H40)<3,"",IF(AND(F40=1,G40=1,H40=1),1,0)) -> 1 | J40: 1 | K40: 01 - Aide à l’utilisation
A41: 101929135 | F41: 1 | G41: 1 | H41: 1 | I41: =IF(COUNTA(F41:H41)<3,"",IF(AND(F41=1,G41=1,H41=1),1,0)) -> 1 | J41: 1 | K41: Conforme
A42: 101903687 | F42: 1 | G42: 1 | H42: 1 | I42: =IF(COUNTA(F42:H42)<3,"",IF(AND(F42=1,G42=1,H42=1),1,0)) -> 1 | J42: 1 | K42: Conforme
A43: 101979421 | F43: 1 | G43: 1 | H43: 0 | I43: =IF(COUNTA(F43:H43)<3,"",IF(AND(F43=1,G43=1,H43=1),1,0)) -> 0 | J43: 1 | K43: Conforme
A44: 101945076 | F44: 1 | G44: 1 | H44: 1 | I44: =IF(COUNTA(F44:H44)<3,"",IF(AND(F44=1,G44=1,H44=1),1,0)) -> 1 | J44: 1 | K44: 01 - Aide à l’utilisation
A45: 102029208 | F45: 1 | G45: 1 | H45: 1 | I45: =IF(COUNTA(F45:H45)<3,"",IF(AND(F45=1,G45=1,H45=1),1,0)) -> 1 | J45: 1 | K45: Conforme
A46: 102094681 | F46: 1 | G46: 1 | H46: 1 | I46: =IF(COUNTA(F46:H46)<3,"",IF(AND(F46=1,G46=1,H46=1),1,0)) -> 1 | J46: 1 | K46: Conforme
A47: 102020926 | F47: 1 | G47: 1 | H47: 1 | I47: =IF(COUNTA(F47:H47)<3,"",IF(AND(F47=1,G47=1,H47=1),1,0)) -> 1 | J47: 1 | K47: Conforme
A48: 101553287 | F48: 1 | G48: 1 | H48: 1 | I48: =IF(COUNTA(F48:H48)<3,"",IF(AND(F48=1,G48=1,H48=1),1,0)) -> 1 | J48: 1 | K48: Conforme
... A56: 101820338 | F56: 1 | G56: 1 | H56: 1 | I56: =IF(COUNTA(F56:H56)<3,"",IF(AND(F56=1,G56=1,H56=1),1,0)) -> 1 | J56: 1 | K56: Conforme
A57: 101972013 | F57: 1 | G57: 1 | H57: 1 | I57: =IF(COUNTA(F57:H57)<3,"",IF(AND(F57=1,G57=1,H57=1),1,0)) -> 1 | J57: 0 | K57: 03 - Script, fix ou contournement | M57: Type de résolution incohérent
A58: 102052236 | F58: 1 | G58: 1 | H58: 1 | I58: =IF(COUNTA(F58:H58)<3,"",IF(AND(F58=1,G58=1,H58=1),1,0)) -> 1 | J58: 1 | K58: Conforme
A59: 102047416 | F59: 1 | G59: 1 | H59: 1 | I59: =IF(COUNTA(F59:H59)<3,"",IF(AND(F59=1,G59=1,H59=1),1,0)) -> 1 | J59: 1 | K59: Conforme
A60: 101421291 | F60: 1 | G60: 1 | H60: 1 | I60: =IF(COUNTA(F60:H60)<3,"",IF(AND(F60=1,G60=1,H60=1),1,0)) -> 1 | J60: 1 | K60: Conforme
A61: 102123134 | F61: 1 | G61: 1 | H61: 1 | I61: =IF(COUNTA(F61:H61)<3,"",IF(AND(F61=1,G61=1,H61=1),1,0)) -> 1 | J61: 1 | K61: Conforme
...

Sheet Rejets
A1: Résponsable | B1: Bannette | C1: Motif du rejet | D1: Action | E1: ID TICKET | F1: TYPE | G1: TITRE | H1: SERVICE IMPACTANT | I1: SERVICE IMPACTE | J1: DIGITAL SUPPORT | K1: CATEGORISATION | L1: DATE CREATION | M1: PRIORITE INITIALE | N1: PRIORITE | O1: BANNETTE RESOLUTION | P1: DOMAINE | Q1: EMPLACEMENT | R1: BU EMPLACEMENT | S1: STATUT | T1: TYPE CIBLE | U1: ETAT CIBLE | V1: DATE RESOLUTION | W1: DUREE TTR (H) | X1: CIBLE (H) | Y1: ETAT TTR | Z1: REAFFECTATIONS | AA1: RELANCES | AB1: REOUVERTURES | AC1: HO HNO | AD1: INCIDENT LIE | AE1: ID ODM
A2: =VLOOKUP(O2,Dictionnaire!A:B,2,0) -> Mouad Bounouar | B2: =O2 -> FR IT SIC N1_N2 PROMOCASH BACK OFFICE | E2: 118396606 | F2: DS | G2: Activer imprimante sur Aquilon | H2: AQUILON-FR | I2: AQUILON-FR | J2: DS Magasin | K2: Back Office Promocash \ Commande \ Commande automatique | L2: ########## | M2: P4 | N2: P4 | O2: FR IT SIC N1_N2 PROMOCASH BACK OFFICE | P2: IT | Q2: ALES - PROMOCASH | R2: PROMOCASH | S2: FranchisÃ© | T2: ExÃ©cution | U2: Atteint | V2: ########## | W2: 155.81 | X2: 180 | Y2: OK | Z2: 5 | AA2: 0 | AB2: 4 | AC2: HO
A3: =VLOOKUP(O3,Dictionnaire!A:B,2,0) -> Mouad Bounouar | B3: =O3 -> FR IT SIC N1_N2 PROMOCASH BACK OFFICE | E3: 121470954 | F3: DA | G3: information sur aquilon Windows | H3: PROMOCASH MARKETING CLOUD-FR | I3: PROMOCASH MARKETING CLOUD-FR | J3: DS Magasin | K3: Back Office Promocash | L3: ########## | M3: P4 | N3: P4 | O3: FR IT SIC N1_N2 PROMOCASH BACK OFFICE | P3: IT | Q3: MACON -VARENNES LES - PROMOCASH | R3: PROMOCASH | S3: FranchisÃ© | T3: RÃ©solution | U3: Echec | V3: ########## | W3: 70.64 | X3: 45 | Y3: KO | Z3: 4 | AA3: 0 | AB3: 1 | AC3: HO
A4: =VLOOKUP(O4,Dictionnaire!A:B,2,0) -> Mouad Bounouar | B4: =O4 -> FR IT SIC N1_N2 PROMOCASH BACK OFFICE | E4: 122479425 | F4: DA | G4: Document bloquÃ© sur la file d'impression | H4: AQUILON-FR | I4: AQUILON-FR | J4: DS Magasin | K4: Back Office Promocash \ Impression | L4: ########## | M4: P4 | N4: P4 | O4: FR IT SIC N1_N2 PROMOCASH BACK OFFICE | P4: IT | Q4: BORDEAUX - PROMOCASH | R4: PROMOCASH | S4: FranchisÃ© | T4: RÃ©solution | U4: Atteint | V4: ########## | W4: 2.27 | X4: 45 | Y4: OK | Z4: 0 | AA4: 0 | AB4: 1 | AC4: HO
A5: =VLOOKUP(O5,Dictionnaire!A:B,2,0) -> Mouad Bounouar | B5: =O5 -> FR IT SIC N1_N2 PROMOCASH BACK OFFICE | E5: 123201848 | F5: DA | G5: Aquilon | H5: AQUILON-FR | I5: AQUILON-FR | J5: DS Magasin | K5: Acces \ Application \ Application KO | L5: ########## | M5: P2 | N5: P2 | O5: FR IT SIC N1_N2 PROMOCASH BACK OFFICE | P5: IT | Q5: LE PUY EN VELAY -CHA - PROMOCASH | R5: PROMOCASH | S5: FranchisÃ© | T5: RÃ©solution | U5: Atteint | V5: ########## | W5: 0.06 | X5: 18 | Y5: OK | Z5: 0 | AA5: 0 | AB5: 1 | AC5: HO
A6: =VLOOKUP(O6,Dictionnaire!A:B,2,0) -> Mouad Bounouar | B6: =O6 -> FR IT SIC N1_N2 PROMOCASH BACK OFFICE | E6: 123385451 | F6: DS | G6: dÃ©blocage client | H6: AQUILON-FR | I6: AQUILON-FR | J6: DS Magasin | K6: Back Office Promocash \ Client | L6: ########## | M6: P4 | N6: P4 | O6: FR IT SIC N1_N2 PROMOCASH BACK OFFICE | P6: IT | Q6: CARCASSONNE - PROMOCASH | R6: PROMOCASH | S6: FranchisÃ© | T6: ExÃ©cution | U6: Atteint | V6: ########## | W6: 12.46 | X6: 180 | Y6: OK | Z6: 6 | AA6: 0 | AB6: 1 | AC6: HO
A7: =VLOOKUP(O7,Dictionnaire!A:B,2,0) -> Mouad Bounouar | B7: =O7 -> FR IT SIC N1_N2 PROMOCASH BACK OFFICE | E7: 123452881 | F7: DA | G7: AUCUNE DESCENTE DE MODEM DE LIVRAISON | H7: AQUILON-FR | I7: AQUILON-FR | J7: DS Magasin | K7: Back Office Promocash \ Reception \ Modem | L7: ########## | M7: P2 | N7: P2 | O7: FR IT SIC N1_N2 PROMOCASH BACK OFFICE | P7: IT | Q7: ANGERS - PROMOCASH | R7: PROMOCASH | S7: FranchisÃ© | T7: RÃ©solution | U7: Atteint | V7: ########## | W7: 9.90 | X7: 18 | Y7: OK | Z7: 1 | AA7: 0 | AB7: 1 | AC7: HO | AD7: 123918877
A8: =VLOOKUP(O8,Dictionnaire!A:B,2,0) -> Mouad Bounouar | B8: =O8 -> FR IT SIC N1_N2 PROMOCASH BACK OFFICE | E8: 123850744 | F8: DA | G8: MODEMS | H8: AQUILON-FR | I8: AQUILON-FR | J8: DS Magasin | K8: Back Office Promocash | L8: ########## | M8: P2 | N8: P2 | O8: FR IT SIC N1_N2 PROMOCASH BACK OFFICE | P8: IT | Q8: GAP - PROMOCASH | R8: PROMOCASH | S8: FranchisÃ© | T8: RÃ©solution | U8: Atteint | V8: ########## | W8: 3.41 | X8: 18 | Y8: OK | Z8: 6 | AA8: 0 | AB8: 2 | AC8: HNO
A9: =VLOOKUP(O9,Dictionnaire!A:B,2,0) -> Mouad Bounouar | B9: =O9 -> FR IT SIC N1_N2 PROXIMITE | E9: 122270764 | F9: DA | G9: UG des produits qui disparait | H9: METI STORE-FR | I9: METI STORE-FR | J9: DS Magasin | K9: Back Office Proximite | L9: ########## | M9: P2 | N9: P2 | O9: FR IT SIC N1_N2 PROXIMITE | P9: IT | Q9: HUSSIGNY -HOPITAL - PROXIMITE | R9: PROXIMITE | S9: FranchisÃ© | T9: RÃ©solution | U9: Echec | V9: ########## | W9: 32.13 | X9: 18 | Y9: KO | Z9: 2 | AA9: 0 | AB9: 1 | AC9: HNO
A10: =VLOOKUP(O10,Dictionnaire!A:B,2,0) -> Mouad Bounouar | B10: =O10 -> FR IT SIC N1_N2 PROXIMITE | E10: 122395503 | F10: DA | G10: non Ã©dition des recapitulatif des mouvements de rÃ©gularisation | H10: REEVA-FR | I10: REEVA-FR | J10: DS Magasin | K10: Back Office Multi format \ Mobilite \ Controle facture | L10: ########## | M10: P4 | N10: P4 | O10: FR IT SIC N1_N2 PROXIMITE | P10: IT | Q10: TOULOUSE -PUJOL 68 - PROXIMITE | R10: PROXIMITE | S10: LG | T10: RÃ©solution | U10: Atteint | V10: ########## | W10: 24.48 | X10: 45 | Y10: OK | Z10: 3 | AA10: 0 | AB10: 1 | AC10: HO
A11: =VLOOKUP(O11,Dictionnaire!A:B,2,0) -> Mouad Bounouar | B11: =O11 -> FR IT SIC N1_N2 PROXIMITE | E11: 122677453 | F11: DA | G11: souci sortie musique | H11: LOGICIEL | I11: MUSIQUE MOODMEDIA-FR | J11: DS Magasin | K11: Back Office Proximite \ Parametrage | L11: ########## | M11: P4 | N11: P4 | O11: FR IT SIC N1_N2 PROXIMITE | P11: IT | Q11: PERIGUEUX -REPUBLIQ - PROXIMITE | R11: PROXIMITE | S11: LG | T11: RÃ©solution | U11: Atteint | V11: ########## | W11: 14.23 | X11: 45 | Y11: OK | Z11: 2 | AA11: 0 | AB11: 3 | AC11: HO
A12: =VLOOKUP(O12,Dictionnaire!A:B,2,0) -> Mouad Bounouar | B12: =O12 -> FR IT SIC N1_N2 PROXIMITE | E12: 122947548 | F12: DA | G12: METI : N A PAS EU LA REMONTEE METI | H12: METI STORE-FR | I12: METI STORE-FR | J12: DS Magasin | K12: Back Office Proximite \ Chiffre d affaire \ Ecart CA | L12: ########## | M12: P4 | N12: P4 | O12: FR IT SIC N1_N2 PROXIMITE | P12: IT | Q12: COMBS LA VIL -QUINCY - PROXIMITE | R12: PROXIMITE | S12: LG | T12: RÃ©solution | U12: Atteint | V12: ########## | W12: 0.00 | X12: 45 | Y12: OK | Z12: 1 | AA12: 0 | AB12: 1 | AC12: HNO
A13: =VLOOKUP(O13,Dictionnaire!A:B,2,0) -> Mouad Bounouar | B13: =O13 -> FR IT SIC N1_N2 PROXIMITE | E13: 122957037 | F13: DA | G13: Refresh | H13: METI STORE-FR | I13: METI STORE-FR | J13: DS Magasin | K13: Back Office Proximite \ Article \ Referentiel | L13: ########## | M13: P2 | N13: P2 | O13: FR IT SIC N1_N2 PROXIMITE | P13: IT | Q13: ST-MARTIN-BELLEVUE - PROXIMITE | R13: PROXIMITE | S13: FranchisÃ© | T13: RÃ©solution | U13: Atteint | V13: ########## | W13: 13.76 | X13: 18 | Y13: OK | Z13: 2 | AA13: 0 | AB13: 3 | AC13: HNO
A14: =VLOOKUP(O14,Dictionnaire!A:B,2,0) -> Mouad Bounouar | B14: =O14 -> FR IT SIC N1_N2 PROXIMITE | E14: 122992712 | F14: DA | G14: METI : N A PAS EU LA REMONTEE METI | H14: METI STORE-FR | I14: METI STORE-FR | J14: DS Magasin | K14: Back Office Proximite | L14: ########## | M14: P4 | N14: P4 | O14: FR IT SIC N1_N2 PROXIMITE | P14: IT | Q14: PARIS -ND DE LORETTE - PROXIMITE | R14: PROXIMITE | S14: FranchisÃ© | T14: RÃ©solution | U14: Atteint | V14: ########## | W14: 36.19 | X14: 60 | Y14: OK | Z14: 11 | AA14: 0 | AB14: 1 | AC14: HNO
A15: =VLOOKUP(O15,Dictionnaire!A:B,2,0) -> Mouad Bounouar | B15: =O15 -> FR IT SIC N1_N2 PROXIMITE | E15: 123002323 | F15: DA | G15: Envoie en caisse | H15: METI STORE-FR | I15: METI STORE-FR | J15: DS Magasin | K15: Back Office Proximite \ Livre de caisse | L15: ########## | M15: P4 | N15: P4 | O15: FR IT SIC N1_N2 PROXIMITE | P15: IT | Q15: BOURGOIN JALLIEU - SUPECO | R15: DISCOUNT SUPERMARCHES | S15: FranchisÃ© | T15: RÃ©solution | U15: Atteint | V15: ########## | W15: 9.44 | X15: 45 | Y15: OK | Z15: 2 | AA15: 0 | AB15: 2 | AC15: HNO
A16: =VLOOKUP(O16,Dictionnaire!A:B,2,0) -> Mouad Bounouar | B16: =O16 -> FR IT SIC N1_N2 PROXIMITE | E16: 123167199 | F16: DA | G16: Doublon - Envoie en caisse | H16: METI STORE-FR | I16: METI STORE-FR | J16: DS Magasin | K16: Back Office Proximite \ Livre de caisse | L16: ########## | M16: P4 | N16: P4 | O16: FR IT SIC N1_N2 PROXIMITE | P16: IT | Q16: BOURGOIN JALLIEU - SUPECO | R16: DISCOUNT SUPERMARCHES | S16: FranchisÃ© | T16: RÃ©solution | U16: Atteint | V16: ########## | W16: 0.20 | X16: 45 | Y16: OK | Z16: 0 | AA16: 0 | AB16: 1 | AC16: HO
A17: =VLOOKUP(O17,Dictionnaire!A:B,2,0) -> Mouad Bounouar | B17: =O17 -> FR IT SIC N1_N2 PROXIMITE | E17: 123667863 | F17: DA | G17: Soufflenheim - Suppression inventaire nÃ©120 | H17: METI STORE-FR | I17: METI STORE-FR | J17: DS Magasin | K17: Back Office Proximite \ Inventaire \ Suppression inventaire | L17: ########## | M17: P2 | N17: P2 | O17: FR IT SIC N1_N2 PROXIMITE | P17: IT | Q17: SOUFFLENHEIM -GR.RUE - PROXIMITE | R17: PROXIMITE | S17: LG | T17: RÃ©solution | U17: Atteint | V17: ########## | W17: 7.71 | X17: 18 | Y17: OK | Z17: 2 | AA17: 0 | AB17: 1 | AC17: HO
A18: =VLOOKUP(O18,Dictionnaire!A:B,2,0) -> Mouad Bounouar | B18: =O18 -> FR IT SIC N1_N2 PROXIMITE | E18: 123706844 | F18: DA | G18: MAJ stock / TEST / RICARD | H18: METIMOBILE (PROXI)-FR | I18: METIMOBILE (PROXI)-FR | J18: DS Magasin | K18: Back Office Proximite \ Stock \ Mouvement | L18: ########## | M18: P5 | N18: P5 | O18: FR IT SIC N1_N2 PROXIMITE | P18: IT | Q18: SAINT-GREGOIRE -FORG - PROXIMITE | R18: PROXIMITE | S18: LG | T18: RÃ©solution | U18: Atteint | V18: ########## | W18: 46186 | X18: 45 | Y18: OK | Z18: 0 | AA18: 0 | AB18: 1 | AC18: HO
A19: =VLOOKUP(O19,Dictionnaire!A:B,2,0) -> Mouad Bounouar | B19: =O19 -> FR IT SIC N1_N2 PROXIMITE | E19: 124264750 | F19: DA | G19: AUCUN MODEM | H19: PROLOG-FR | I19: AQUILON-FR | J19: DS Magasin | K19: Back Office Promocash \ Reception \ Modem | L19: ########## | M19: P4 | N19: P4 | O19: FR IT SIC N1_N2 PROXIMITE | P19: IT | Q19: BOURG EN BRESSE - PROMOCASH | R19: PROMOCASH | S19: FranchisÃ© | T19: RÃ©solution | U19: Atteint | V19: ########## | W19: 4.95 | X19: 45 | Y19: OK | Z19: 6 | AA19: 0 | AB19: 1 | AC19: HNO
A20: =VLOOKUP(O20,Dictionnaire!A:B,2,0) -> Mohamed BENSAID | B20: =O20 -> FR IT SIC N1_N2 SUPER-HYPER BACK OFFICE | E20: 121813044 | F20: DA | G20: Erreur Nomencature SM | H20: CAROLINE HYPER-FR | I20: CAROLINE HYPER-FR | J20: DS Magasin | K20: Back Office Hyper \ Referentiel \ Modification donnee article | L20: ########## | M20: P2 | N20: P2 | O20: FR IT SIC N1_N2 SUPER-HYPER BACK OFFICE | P20: IT | Q20: DIR COMMERCIALE FR (DIR COMMERCIALE FR) | R20: DIR MARCHANDISES | S20: SiÃ¨ge | T20: RÃ©solution | U20: Echec | V20: ########## | W20: 26.74 | X20: 18 | Y20: KO | Z20: 5 | AA20: 0 | AB20: 1 | AC20: HO
A21: =VLOOKUP(O21,Dictionnaire!A:B,2,0) -> Mohamed BENSAID | B21: =O21 -> FR IT SIC N1_N2 SUPER-HYPER BACK OFFICE | E21: 121948632 | F21: DA | G21: etiquette | H21: CAROMOBILE-FR | I21: CAROLINE SUPER-FR | J21: DS Magasin | K21: Back Office Super \ Referentiel | L21: ########## | M21: P1 | N21: P4 | O21: FR IT SIC N1_N2 SUPER-HYPER BACK OFFICE | P21: IT | Q21: NEUILLY EN THELLE - SUPERMARCHES | R21: SUPERMARCHES FRANCE | S21: LG | T21: RÃ©solution | U21: Atteint | V21: ########## | W21: 5.67 | X21: 45 | Y21: OK | Z21: 0 | AA21: 0 | AB21: 1 | AC21: HNO
A22: =VLOOKUP(O22,Dictionnaire!A:B,2,0) -> Mohamed BENSAID | B22: =O22 -> FR IT SIC N1_N2 SUPER-HYPER BACK OFFICE | E22: 122003791 | F22: DA | G22: problÃ©me de produit rayon | H22: CAROLINE HYPER-FR | I22: CAROLINE HYPER-FR | J22: DS Magasin | K22: Back Office Hyper \ Referentiel \ Modification donnee article | L22: ########## | M22: P1 | N22: P3 | O22: FR IT SIC N1_N2 SUPER-HYPER BACK OFFICE | P22: IT | Q22: PORT DE BOUC - HYPERMARCHES | R22: HYPERMARCHES FRANCE | S22: LG | T22: RÃ©solution | U22: Atteint | V22: ########## | W22: 11.34 | X22: 27 | Y22: OK | Z22: 4 | AA22: 0 | AB22: 2 | AC22: HNO
A23: =VLOOKUP(O23,Dictionnaire!A:B,2,0) -> Mohamed BENSAID | B23: =O23 -> FR IT SIC N1_N2 SUPER-HYPER BACK OFFICE | E23: 122242280 | F23: DS | G23: Changement IFLS pour le EAN 3492500066001 sur Caroline | H23: BCP-FR | I23: CAROLINE HYPER-FR | J23: DS Magasin | K23: Back Office Hyper \ Gestion des retours | L23: ########## | M23: P3 | N23: P3 | O23: FR IT SIC N1_N2 SUPER-HYPER BACK OFFICE | P23: IT | Q23: WITTENHEIM - HYPERMARCHES | R23: HYPERMARCHES FRANCE | S23: IntÃ©grÃ© | T23: ExÃ©cution | U23: Atteint | V23: ########## | W23: 46.35 | X23: 66 | Y23: OK | Z23: 6 | AA23: 0 | AB23: 1 | AC23: HO
A24: =VLOOKUP(O24,Dictionnaire!A:B,2,0) -> Mohamed BENSAID | B24: =O24 -> FR IT SIC N1_N2 SUPER-HYPER BACK OFFICE | E24: 122302633 | F24: DA | G24: ProcÃ©dure terminÃ©e confirmÃ© par le magasin | H24: CAROLINE HYPER-FR | I24: CAROLINE HYPER-FR | J24: DS Magasin | K24: Back Office Hyper \ Gestion des retours \ Bon de retour | L24: ########## | M24: P4 | N24: P3 | O24: FR IT SIC N1_N2 SUPER-HYPER BACK OFFICE | P24: IT | Q24: VENETTE - HYPERMARCHES | R24: HYPERMARCHES FRANCE | S24: IntÃ©grÃ© | T24: RÃ©solution | U24: Atteint | V24: ########## | W24: 16.71 | X24: 27 | Y24: OK | Z24: 0 | AA24: 0 | AB24: 1 | AC24: HNO
A25: =VLOOKUP(O25,Dictionnaire!A:B,2,0) -> Mohamed BENSAID | B25: =O25 -> FR IT SIC N1_N2 SUPER-HYPER BACK OFFICE | E25: 122328683 | F25: DA | G25: CA | H25: SMARTPOS-FR | I25: CAROLINE SUPER-FR | J25: DS Magasin | K25: Data BI \ Donnee \ Qualite | L25: ########## | M25: P3 | N25: P3 | O25: FR IT SIC N1_N2 SUPER-HYPER BACK OFFICE | P25: IT | Q25: VILLEVIEILLE - SUPERMARCHES | R25: SUPERMARCHES FRANCE | S25: IntÃ©grÃ© | T25: RÃ©solution | U25: Atteint | V25: ########## | W25: 25.91 | X25: 27 | Y25: OK | Z25: 3 | AA25: 0 | AB25: 1 | AC25: HO
A26: =VLOOKUP(O26,Dictionnaire!A:B,2,0) -> Mohamed BENSAID | B26: =O26 -> FR IT SIC N1_N2 SUPER-HYPER BACK OFFICE | E26: 122354503 | F26: DA | G26: TONDEUSE GARDENA | H26: CAROLINE SUPER-FR | I26: CAROLINE SUPER-FR | J26: DS Magasin | K26: Back Office Super \ Tarification \ Prix de vente | L26: ########## | M26: P3 | N26: P3 | O26: FR IT SIC N1_N2 SUPER-HYPER BACK OFFICE | P26: IT | Q26: BADEN - SUPERMARCHES | R26: SUPERMARCHES FRANCE | S26: FranchisÃ© | T26: RÃ©solution | U26: Atteint | V26: ########## | W26: 1.63 | X26: 27 | Y26: OK | Z26: 0 | AA26: 0 | AB26: 1 | AC26: HO
A27: =VLOOKUP(O27,Dictionnaire!A:B,2,0) -> Mohamed BENSAID | B27: =O27 -> FR IT SIC N1_N2 SUPER-HYPER BACK OFFICE | E27: 122521409 | F27: DA | G27: ProblÃ©me connexion Caroline et lenteur sur TR | H27: CAROLINE SUPER-FR | I27: CAROLINE SUPER-FR | J27: DS Magasin | K27: Acces \ Application \ Application KO | L27: ########## | M27: P3 | N27: P3 | O27: FR IT SIC N1_N2 SUPER-HYPER BACK OFFICE | P27: IT | Q27: LILLERS -DEKEISER - SUPERMARCHES | R27: SUPERMARCHES FRANCE | S27: IntÃ©grÃ© | T27: RÃ©solution | U27: Atteint | V27: ########## | W27: 9.00 | X27: 27 | Y27: OK | Z27: 0 | AA27: 0 | AB27: 1 | AC27: HNO
A28: =VLOOKUP(O28,Dictionnaire!A:B,2,0) -> Mohamed BENSAID | B28: =O28 -> FR IT SIC N1_N2 SUPER-HYPER BACK OFFICE | E28: 122527244 | F28: DA | G28: modifier 5 PV bloquer par enveloppe promo | H28: CAROLINE SUPER-FR | I28: CAROLINE SUPER-FR | J28: DS Magasin | K28: Back Office Super \ Tarification \ Prix de vente | L28: ########## | M28: P1 | N28: P2 | O28: FR IT SIC N1_N2 SUPER-HYPER BACK OFFICE | P28: IT | Q28: BRAM - SUPERMARCHES | R28: SUPERMARCHES FRANCE | S28: FranchisÃ© | T28: RÃ©solution | U28: Atteint | V28: ########## | W28: 5.56 | X28: 18 | Y28: OK | Z28: 0 | AA28: 0 | AB28: 2 | AC28: HNO
A29: =VLOOKUP(O29,Dictionnaire!A:B,2,0) -> Mohamed BENSAID | B29: =O29 -> FR IT SIC N1_N2 SUPER-HYPER BACK OFFICE | E29: 122570579 | F29: DA | G29: z- Autre | H29: CAROLINE HYPER-FR | I29: CAROLINE HYPER-FR | J29: DS Magasin | K29: Back Office Hyper \ Tarification \ Prix d achat | L29: ########## | M29: P2 | N29: P2 | O29: FR IT SIC N1_N2 SUPER-HYPER BACK OFFICE | P29: IT | Q29: ST JOUAN DES GUERETS - HYPERMARCHES | R29: HYPERMARCHES FRANCE | S29: IntÃ©grÃ© | T29: RÃ©solution | U29: Atteint | V29: ########## | W29: 4.18 | X29: 18 | Y29: OK | Z29: 0 | AA29: 0 | AB29: 1 | AC29: HO
A30: =VLOOKUP(O30,Dictionnaire!A:B,2,0) -> Mohamed BENSAID | B30: =O30 -> FR IT SIC N1_N2 SUPER-HYPER BACK OFFICE | E30: 122573647 | F30: DA | G30: PVB/PVC | H30: CAROLINE HYPER-FR | I30: CAROLINE HYPER-FR | J30: DS Magasin | K30: Back Office Hyper \ Tarification \ Prix d achat | L30: ########## | M30: P1 | N30: P4 | O30: FR IT SIC N1_N2 SUPER-HYPER BACK OFFICE | P30: IT | Q30: PORT DE BOUC - HYPERMARCHES | R30: HYPERMARCHES FRANCE | S30: LG | T30: RÃ©solution | U30: Atteint | V30: ########## | W30: 1.90 | X30: 45 | Y30: OK | Z30: 0 | AA30: 0 | AB30: 1 | AC30: HO
... A40: =VLOOKUP(O40,Dictionnaire!A:B,2,0) -> Mohamed BENSAID | B40: =O40 -> FR IT SIC N1_N2 SUPER-HYPER BACK OFFICE | E40: 123210960 | F40: DA | G40: Ecart proforma et financier | H40: CAROLINE SUPER-FR | I40: VLP SUPER-FR | J40: DS Magasin | K40: Encaissement \ Chiffre d affaire \ Ecart de CA | L40: ########## | M40: P3 | N40: P4 | O40: FR IT SIC N1_N2 SUPER-HYPER BACK OFFICE | P40: IT | Q40: OULLINS - SUPERMARCHES | R40: SUPERMARCHES FRANCE | S40: FranchisÃ© | T40: RÃ©solution | U40: Atteint | V40: ########## | W40: 5.20 | X40: 60 | Y40: OK | Z40: 1 | AA40: 0 | AB40: 1 | AC40: HO
A41: =VLOOKUP(O41,Dictionnaire!A:B,2,0) -> Mohamed BENSAID | B41: =O41 -> FR IT SIC N1_N2 SUPER-HYPER BACK OFFICE | E41: 123214288 | F41: DA | G41: Ã©cart sur le chiffre d'affaire 14 avril | H41: CAROLINE SUPER-FR | I41: CAROLINE SUPER-FR | J41: DS Magasin | K41: Back Office Super \ Chiffre d affaire | L41: ########## | M41: P3 | N41: P3 | O41: FR IT SIC N1_N2 SUPER-HYPER BACK OFFICE | P41: IT | Q41: CAZOULS LES BEZIERS - SUPERMARCHES | R41: SUPERMARCHES FRANCE | S41: FranchisÃ© | T41: RÃ©solution | U41: Atteint | V41: ########## | W41: 46154 | X41: 27 | Y41: OK | Z41: 2 | AA41: 0 | AB41: 1 | AC41: HO
A42: =VLOOKUP(O42,Dictionnaire!A:B,2,0) -> Mohamed BENSAID | B42: =O42 -> FR IT SIC N1_N2 SUPER-HYPER BACK OFFICE | E42: 123266939 | F42: DA | G42: ARTICLE INEXISTANT MAIS IMPOSSIBLE DE LE CREER | H42: CAROLINE HYPER-FR | I42: CAROLINE HYPER-FR | J42: DS Magasin | K42: Back Office Hyper \ Referentiel \ Article inconnu | L42: ########## | M42: P3 | N42: P3 | O42: FR IT SIC N1_N2 SUPER-HYPER BACK OFFICE | P42: IT | Q42: MONTAUBAN - HYPERMARCHES | R42: HYPERMARCHES FRANCE | S42: FranchisÃ© | T42: RÃ©solution | U42: Atteint | V42: ########## | W42: 17.22 | X42: 27 | Y42: OK | Z42: 0 | AA42: 0 | AB42: 1 | AC42: HO
A43: =VLOOKUP(O43,Dictionnaire!A:B,2,0) -> Mohamed BENSAID | B43: =O43 -> FR IT SIC N1_N2 SUPER-HYPER BACK OFFICE | E43: 123320167 | F43: DA | G43: Suppression urgente EAN 8423230000305 vente Ã© perte | H43: CAROLINE HYPER-FR | I43: CAROLINE HYPER-FR | J43: DS Magasin | K43: Back Office Hyper \ Inventaire \ Annulation / suppression | L43: ########## | M43: P2 | N43: P1 | O43: FR IT SIC N1_N2 SUPER-HYPER BACK OFFICE | P43: IT | Q43: MONACO - HYPERMARCHES | R43: HYPERMARCHES FRANCE | S43: IntÃ©grÃ© | T43: RÃ©solution | U43: Atteint | V43: ########## | W43: 6.44 | X43: 9 | Y43: OK | Z43: 1 | AA43: 0 | AB43: 1 | AC43: HNO
A44: =VLOOKUP(O44,Dictionnaire!A:B,2,0) -> Mohamed BENSAID | B44: =O44 -> FR IT SIC N1_N2 SUPER-HYPER BACK OFFICE | E44: 123371536 | F44: DA | G44: CREME | H44: CAROLINE HYPER-FR | I44: CAROLINE HYPER-FR | J44: DS Magasin | K44: Back Office Hyper \ Referentiel \ Modification donnee article | L44: ########## | M44: P1 | N44: P3 | O44: FR IT SIC N1_N2 SUPER-HYPER BACK OFFICE | P44: IT | Q44: VILLEFRANCHE DE ROUE - HYPERMARCHES | R44: HYPERMARCHES FRANCE | S44: LG | T44: RÃ©solution | U44: Atteint | V44: ########## | W44: 5.39 | X44: 27 | Y44: OK | Z44: 0 | AA44: 0 | AB44: 2 | AC44: HO
A45: =VLOOKUP(O45,Dictionnaire!A:B,2,0) -> Mohamed BENSAID | B45: =O45 -> FR IT SIC N1_N2 SUPER-HYPER BACK OFFICE | E45: 123399176 | F45: DA | G45: ACCES IMPOSSIBLE AU MENU INVENTAIRE POUR UNE MANAGER | H45: CAROLINE HYPER-FR | I45: CAROLINE HYPER-FR | J45: DS Magasin | K45: Acces \ Application \ Droit GDI | L45: ########## | M45: P2 | N45: P2 | O45: FR IT SIC N1_N2 SUPER-HYPER BACK OFFICE | P45: IT | Q45: FERNEY VOLTAIRE - HYPERMARCHES | R45: HYPERMARCHES FRANCE | S45: FranchisÃ© | T45: RÃ©solution | U45: Atteint | V45: ########## | W45: 12.55 | X45: 18 | Y45: OK | Z45: 0 | AA45: 0 | AB45: 1 | AC45: HO
A46: =VLOOKUP(O46,Dictionnaire!A:B,2,0) -> Mohamed BENSAID | B46: =O46 -> FR IT SIC N1_N2 SUPER-HYPER BACK OFFICE | E46: 123454896 | F46: DA | G46: Demande de facture fournisseur | H46: CAROLINE HYPER-FR | I46: CAROLINE HYPER-FR | J46: DS Magasin | K46: Back Office Hyper \ Commande | L46: ########## | M46: P3 | N46: P3 | O46: FR IT SIC N1_N2 SUPER-HYPER BACK OFFICE | P46: IT | Q46: EVREUX -SAINT TAURIN - HYPERMARCHES | R46: HYPERMARCHES FRANCE | S46: IntÃ©grÃ© | T46: RÃ©solution | U46: Atteint | V46: ########## | W46: 1.00 | X46: 27 | Y46: OK | Z46: 0 | AA46: 0 | AB46: 1 | AC46: HO
A47: =VLOOKUP(O47,Dictionnaire!A:B,2,0) -> Mohamed BENSAID | B47: =O47 -> FR IT SIC N1_N2 SUPER-HYPER BACK OFFICE | E47: 123641447 | F47: DA | G47: Impossible de crÃ©er des zones d?inventaire sur Caroline | H47: CAROLINE HYPER-FR | I47: CAROLINE HYPER-FR | J47: DS Magasin | K47: Back Office Hyper \ Inventaire \ Chiffrage box | L47: ########## | M47: P3 | N47: P3 | O47: FR IT SIC N1_N2 SUPER-HYPER BACK OFFICE | P47: IT | Q47: METZ -TECHNOPOLE - HYPERMARCHES | R47: HYPERMARCHES FRANCE | S47: IntÃ©grÃ© | T47: RÃ©solution | U47: Atteint | V47: ########## | W47: 10.75 | X47: 27 | Y47: OK | Z47: 0 | AA47: 0 | AB47: 1 | AC47: HO | AD47: 123904947
A48: =VLOOKUP(O48,Dictionnaire!A:B,2,0) -> Mohamed BENSAID | B48: =O48 -> FR IT SIC N1_N2 SUPER-HYPER BACK OFFICE | E48: 123658710 | F48: DA | G48: Validation | H48: CAROLINE HYPER-FR | I48: CAROLINE HYPER-FR | J48: DS Magasin | K48: Back Office Hyper \ Inventaire \ Chiffrage box | L48: ########## | M48: P2 | N48: P2 | O48: FR IT SIC N1_N2 SUPER-HYPER BACK OFFICE | P48: IT | Q48: DORLISHEIM -MOLSHEIM - HYPERMARCHES | R48: HYPERMARCHES FRANCE | S48: IntÃ©grÃ© | T48: RÃ©solution | U48: Atteint | V48: ########## | W48: 12.33 | X48: 18 | Y48: OK | Z48: 0 | AA48: 0 | AB48: 1 | AC48: HO | AD48: 123904947
A49: =VLOOKUP(O49,Dictionnaire!A:B,2,0) -> Mohamed BENSAID | B49: =O49 -> FR IT SIC N1_N2 SUPER-HYPER BACK OFFICE | E49: 123691576 | F49: DS | G49: Demande d'integration de SMP dans Caroline sur le SMP Magasin et sur le SMP prÃ©conisÃ© HYPER TEXTILE | H49: CAROLINE HYPER-FR | I49: CAROLINE HYPER-FR | J49: DS Magasin | K49: Back Office Hyper \ Referentiel | L49: ########## | M49: P3 | N49: P3 | O49: FR IT SIC N1_N2 SUPER-HYPER BACK OFFICE | P49: IT | Q49: FRANCE | R49: NON DEFINIE | S49: Non affectÃ© | T49: ExÃ©cution | U49: Atteint | V49: ########## | W49: 0.23 | X49: 66 | Y49: OK | Z49: 0 | AA49: 0 | AB49: 1 | AC49: HO
...

Sheet Publipostage
A1: Date Publi | B1: Semaine | C1: Bannette | D1: Résponsable action | E1: N° Ticket | F1: Adresse mail | G1: Note NPS
A2: 46013 | B2: S52 | C2: Proximité/Promocash | D2: BOUNOUAR Mouad | E2: 101809705 | F2: fabien_durand@carrefour.com
A3: 46013 | B3: S52 | C3: Proximité/Promocash | D3: BOUNOUAR Mouad | E3: 101837157 | F3: damien_declercq@franchise.carrefour.com
A4: 46013 | B4: S52 | C4: Proximité/Promocash | D4: BOUNOUAR Mouad | E4: 101737488 | F4: corine_benardon@franchise.carrefour.com
A5: 46013 | B5: S52 | C5: Proximité/Promocash | D5: BOUNOUAR Mouad | E5: 101805660 | F5: hichem_abdelli@franchise.carrefour.com
A6: 46013 | B6: S52 | C6: Proximité/Promocash | D6: BOUNOUAR Mouad | E6: 101814092 | F6: m_hamed_mellouki@franchise.carrefour.com
A7: 46013 | B7: S52 | C7: Proximité/Promocash | D7: BOUNOUAR Mouad | E7: 101559519 | F7: bertrand_guignard@promocash.com
A8: 46013 | B8: S52 | C8: Proximité/Promocash | D8: BOUNOUAR Mouad | E8: 101611584 | F8: remi_henri_sanchez@franchise.carrefour.com
A9: 46013 | B9: S52 | C9: Proximité/Promocash | D9: BOUNOUAR Mouad | E9: 101821177 | F9: nicolas_peyras@franchise.carrefour.com | G9: 9
A10: 46013 | B10: S52 | C10: Proximité/Promocash | D10: BOUNOUAR Mouad | E10: 101834405 | F10: aude_benedet@franchise.carrefour.com
A11: 46013 | B11: S52 | C11: Proximité/Promocash | D11: BOUNOUAR Mouad | E11: 101786001 | F11: aurore_capron@franchise.carrefour.com
A12: 46013 | B12: S52 | C12: Proximité/Promocash | D12: BOUNOUAR Mouad | E12: 101847244 | F12: francois_bouthemy_1@franchise.carrefour.com
A13: 46013 | B13: S52 | C13: Proximité/Promocash | D13: BOUNOUAR Mouad | E13: 101811661 | F13: yolaine_paris@franchise.carrefour.com | G13: 10
A14: 46013 | B14: S52 | C14: Proximité/Promocash | D14: BOUNOUAR Mouad | E14: 101770801 | F14: maryline_guilbaud@franchise.carrefour.com | G14: 10
A15: 46013 | B15: S52 | C15: Proximité/Promocash | D15: BOUNOUAR Mouad | E15: 101820109 | F15: marine_perre_1@franchise.carrefour.com
A16: 46013 | B16: S52 | C16: Proximité/Promocash | D16: BOUNOUAR Mouad | E16: 101810988 | F16: pierre_yves_reuzeau@franchise.carrefour.com
A17: 46013 | B17: S52 | C17: Proximité/Promocash | D17: BOUNOUAR Mouad | E17: 101812647 | F17: bruno_hay@franchise.carrefour.com
A18: 46013 | B18: S52 | C18: Proximité/Promocash | D18: BOUNOUAR Mouad | E18: 101827588 | F18: sebastien_thillerot_1@franchise.carrefour.com | G18: 10
A19: 46013 | B19: S52 | C19: Proximité/Promocash | D19: BOUNOUAR Mouad | E19: 101680538 | F19: theo_ceze@franchise.carrefour.com
A20: 46013 | B20: S52 | C20: Proximité/Promocash | D20: BOUNOUAR Mouad | E20: 101824975 | F20: jean_jacques_vieilly@carrefour.com
A21: 46013 | B21: S52 | C21: Proximité/Promocash | D21: BOUNOUAR Mouad | E21: 101847118 | F21: francois_bouthemy_1@franchise.carrefour.com
A22: 46014 | B22: S52 | C22: Proximité/Promocash | D22: BOUNOUAR Mouad | E22: 101995278 | F22: morgan_roche_2@franchise.carrefour.com
A23: 46014 | B23: S52 | C23: Proximité/Promocash | D23: BOUNOUAR Mouad | E23: 102116078 | F23: odette_brocheton@franchise.carrefour.com
A24: 46014 | B24: S52 | C24: Proximité/Promocash | D24: BOUNOUAR Mouad | E24: 102116745 | F24: julien_le_scolan@promocash.com
A25: 46014 | B25: S52 | C25: Proximité/Promocash | D25: BOUNOUAR Mouad | E25: 102118052 | F25: tarek_asri_1@franchise.carrefour.com
A26: 46014 | B26: S52 | C26: Proximité/Promocash | D26: BOUNOUAR Mouad | E26: 102047545 | F26: emilien_letourneux@franchise.carrefour.com
A27: 46014 | B27: S52 | C27: Proximité/Promocash | D27: BOUNOUAR Mouad | E27: 101913324 | F27: bernadette_noury@franchise.carrefour.com
A28: 46014 | B28: S52 | C28: Proximité/Promocash | D28: BOUNOUAR Mouad | E28: 101910016 | F28: amar_nemraoui_1@franchise.carrefour.com
A29: 46014 | B29: S52 | C29: Proximité/Promocash | D29: BOUNOUAR Mouad | E29: 101918304 | F29: morandeau_guillaume@franchise.carrefour.com
A30: 46014 | B30: S52 | C30: Proximité/Promocash | D30: BOUNOUAR Mouad | E30: 102056528 | F30: sebastien_duffau_1@franchise.carrefour.com
A31: 46014 | B31: S52 | C31: Proximité/Promocash | D31: BOUNOUAR Mouad | E31: 101923147 | F31: foad_el_imami@franchise.carrefour.com
A32: 46014 | B32: S52 | C32: Proximité/Promocash | D32: BOUNOUAR Mouad | E32: 101923018 | F32: laura_dewasmes@promocash.com
A33: 46014 | B33: S52 | C33: Proximité/Promocash | D33: BOUNOUAR Mouad | E33: 101926890 | F33: martin_carpentier@franchise.carrefour.com
A34: 46014 | B34: S52 | C34: Proximité/Promocash | D34: BOUNOUAR Mouad | E34: 102061037 | F34: elodie_duchenne@promocash.com | G34: 10
A35: 46014 | B35: S52 | C35: Proximité/Promocash | D35: BOUNOUAR Mouad | E35: 102073775 | F35: david_duamelle@franchise.carrefour.com
A36: 46014 | B36: S52 | C36: Proximité/Promocash | D36: BOUNOUAR Mouad | E36: 102078973 | F36: sidy_sow@franchise.carrefour.com
A37: 46014 | B37: S52 | C37: Proximité/Promocash | D37: BOUNOUAR Mouad | E37: 102075277 | F37: sidy_sow@franchise.carrefour.com
A38: 46014 | B38: S52 | C38: Proximité/Promocash | D38: BOUNOUAR Mouad | E38: 101957802 | F38: paul_garcia@franchise.carrefour.com
A39: 46014 | B39: S52 | C39: Proximité/Promocash | D39: BOUNOUAR Mouad | E39: 102087751 | F39: yohann_marguerite@promocash.com
A40: 46014 | B40: S52 | C40: Proximité/Promocash | D40: BOUNOUAR Mouad | E40: 102082128 | F40: sebastien_gleize@franchise.carrefour.com
...

Sheet Détail Agent
A1: Date | B1: (Multiple Items)
A3: Résolu par | B3: Bannette | C3: COUNTA of Type de résolution
A4: Abdelilah SAOUDI | B4: FO | C4: 17
A5: Abdelmoughit ARRABIH | B5: FO | C5: 18
A6: Achraf Bouabdelli | B6: BO | C6: 15
A7: Ahmed EL MESSAOUDI | B7: Partenaire | C7: 12
A8: Alan Nowak | B8: FO
A9: Amina AATATI | B9: BO | C9: 20
A10: Anas FAID | B10: FO | C10: 2
A11: Aya BOURMAILA | B11: Supply
A12: Aymane DOUCHI IDRISSI | B12: BO
A13: Ayoub ABDELLAH | B13: BO | C13: 14
A14: Azzeddine BOUHLAL | B14: FO | C14: 14
A15: Baba mohammed amine | B15: Partenaire | C15: 36
A16: Badr EL MOUAHHID | B16: Supply | C16: 16
A17: Bassma BOUKHLAL | B17: FO | C17: 15
A18: Chaimaa JIRANI | B18: BO | C18: 22
A19: Chaimae EL KADIRI | B19: FO | C19: 22
A20: El Mehdi EL MANSOURI | B20: PROXI-PMC | C20: 13
A21: Fatima Ezzahra AMANNE | B21: FO | C21: 17
A22: fatima Zahra | B22: FO
A23: Hajar ESSABIR | B23: FO | C23: 18
A24: Hamza ABBA | B24: Supply | C24: 23
A25: Hamza MESSAOUDI | B25: Partenaire | C25: 47
B26: PROXI-PMC | C26: 17
B27: Supply
A28: Hassnae HASSIB | B28: FO | C28: 18
A29: Hiba BARICH | B29: PROXI-PMC | C29: 14
A30: Karam ZNIDIGA | B30: FO | C30: 14
A31: Khalid BEKKALI | B31: PROXI-PMC | C31: 1
A32: Majdouline HRAR | B32: FO | C32: 19
A33: Marwane BENHAYMAD | B33: BO | C33: 15
A34: Moad TINOUISSI | B34: Partenaire | C34: 51
A35: Mohamed ARRAJ | B35: BO | C35: 7
A36: Mohamed Sedik MASTARI | B36: PROXI-PMC | C36: 14
A37: Mohammed Amine CHETOUI | B37: BO | C37: 19
A38: Nabil ATIF | B38: PROXI-PMC | C38: 15
A39: Nabil JEBILOU | B39: BO | C39: 12
... A54: Zidane MOUASSINE | B54: PROXI-PMC | C54: 12
A55: (blank) | B55: (blank)
...

Sheet Dictionnaire
A1: Bannete | B1: Résponsable
A2: FR IT SIC N1_N2 PROMOCASH BACK OFFICE | B2: Mouad Bounouar
A3: FR IT SIC N1_N2 PROXIMITE | B3: Mouad Bounouar
A4: FR IT SIC N1_N2 SUPER-HYPER FRONT OFFICE | B4: Yassine RABBAI
A5: FR IT SIC N1_N2 SUPER-HYPER BACK OFFICE | B5: Mohamed BENSAID
A6: FR IT UMA N3 BACK OFFICE MAGASIN | B6: Mohamed BENSAID
A7: FR IT UMA N1 N2 PARTENAIRE MAGASIN | B7: Amine BABA
A8: FR IT SIC N1_N2 SUPPLY | B8: Khalil HABRRMAN
A9: FR IT UMA N3 ENCAISSEMENT HYPER | B9: Yassine RABBAI
